Workbook

Sheet INICIO
B6: PRECIO BASE DD: | C6: 1.297 | F6: Cotización Dólar | J6: http://www.bna.com.ar/
B8: PRECIO BASE NEGRA: | C8: 1.14 | F8: Dólar Definido | J8: 1498
B10: FECHA DE ACTUALIZACIÓN: | D10: 45398 | J10: Buscar | L10: Ctrl + B
D12: clientes | F12: BASE DD | L12: BASE NEGRA
B13: CLIENTES: | F13: % Incremento | G13: Base 100 | H13: Coeficiente | I13: Resultado | J13: Base U$S | K13: Base $ | L13: % Incremento | M13: Base 100 | N13: Coeficiente | O13: Resultado | P13: Base U$S | Q13: Base $
B14: 1 | D14: tato/rolando/alpes/javier/bassaro/El roble | F14: 8 | G14: 0.01 | H14: =PRODUCT(F14,G14) -> 0.08 | I14: =PRODUCT(H14,C6) -> 0.10376 | J14: =SUM(C6,I14) -> 1.40076 | K14: =PRODUCT(J8,J14) -> 2098.3385 | L14: 5 | M14: 0.01 | N14: =PRODUCT(L14,M14) -> 0.05 | O14: =PRODUCT(N14,C8) -> 0.057 | P14: =SUM(C8,O14) -> 1.197 | Q14: =PRODUCT(J8,P14) -> 1793.106
B15: 2 | D15: MARTINEZ/pretocom/parrillas omar/gillio | F15: 8 | G15: 0.01 | H15: =PRODUCT(F15,G15) -> 0.08 | I15: =PRODUCT(H15,C6) -> 0.10376 | J15: =SUM(C6,I15) -> 1.40076 | K15: =PRODUCT(J8,J15) -> 2098.3385 | L15: 5 | M15: 0.01 | N15: =PRODUCT(L15,M15) -> 0.05 | O15: =PRODUCT(N15,C8) -> 0.057 | P15: =SUM(C8,O15) -> 1.197 | Q15: =PRODUCT(J8,P15) -> 1793.106
B16: 3 | D16: megacer/esimet/ravi/sonoflex | F16: 15 | G16: 0.01 | H16: =PRODUCT(F16,G16) -> 0.15 | I16: =PRODUCT(H16,C6) -> 0.19455 | J16: =SUM(C6,I16) -> 1.49155 | K16: =PRODUCT(J8,J16) -> 2234.3419 | L16: 10 | M16: 0.01 | N16: =PRODUCT(L16,M16) -> 0.1 | O16: =PRODUCT(N16,C8) -> 0.114 | P16: =SUM(C8,O16) -> 1.254 | Q16: =PRODUCT(J8,P16) -> 1878.492
B17: 4 | D17: FABRICAL | F17: 12 | G17: 0.01 | H17: =PRODUCT(F17,G17) -> 0.12 | I17: =PRODUCT(H17,C6) -> 0.15564 | J17: =SUM(C6,I17) -> 1.45264 | K17: =PRODUCT(J8,J17) -> 2176.0547 | L17: 7 | M17: 0.01 | N17: =PRODUCT(L17,M17) -> 0.07 | O17: =PRODUCT(N17,C8) -> 0.0798 | P17: =SUM(C8,O17) -> 1.2198 | Q17: =PRODUCT(J8,P17) -> 1827.2604
B18: 5 | D18: PLEG HURLINGHAM/tasia/lujan/san nicolas/mesquitq/santodomingo | F18: 7 | G18: 0.01 | H18: =PRODUCT(F18,G18) -> 0.07 | I18: =PRODUCT(H18,C6) -> 0.09079 | J18: =SUM(C6,I18) -> 1.38779 | K18: =PRODUCT(J8,J18) -> 2078.9094 | L18: 5 | M18: 0.01 | N18: =PRODUCT(L18,M18) -> 0.05 | O18: =PRODUCT(N18,C8) -> 0.057 | P18: =SUM(C8,O18) -> 1.197 | Q18: =PRODUCT(J8,P18) -> 1793.106
B19: 6 | D19: OXPANE LASER/milsa/viane | F19: 6 | G19: 0.01 | H19: =PRODUCT(F19,G19) -> 0.06 | I19: =PRODUCT(H19,C6) -> 0.07782 | J19: =SUM(C6,I19) -> 1.37482 | K19: =PRODUCT(J8,J19) -> 2059.4804 | L19: 1 | M19: 0.01 | N19: =PRODUCT(L19,M19) -> 0.01 | O19: =PRODUCT(N19,C8) -> 0.0114 | P19: =SUM(C8,O19) -> 1.1514 | Q19: =PRODUCT(J8,P19) -> 1724.7972
B20: 7 | D20: GOR GRAS/rase/calcor/fabrica de luz/forjan/lagos | F20: 13 | G20: 0.01 | H20: =PRODUCT(F20,G20) -> 0.13 | I20: =PRODUCT(H20,C6) -> 0.16861 | J20: =SUM(C6,I20) -> 1.46561 | K20: =PRODUCT(J8,J20) -> 2195.4838 | L20: 9 | M20: 0.01 | N20: =PRODUCT(L20,M20) -> 0.09 | O20: =PRODUCT(N20,C8) -> 0.1026 | P20: =SUM(C8,O20) -> 1.2426 | Q20: =PRODUCT(J8,P20) -> 1861.4148
B21: 8 | D21: cormot/geluma/merigui/lumak | F21: 12 | G21: 0.01 | H21: =PRODUCT(F21,G21) -> 0.12 | I21: =PRODUCT(H21,C6) -> 0.15564 | J21: =SUM(C6,I21) -> 1.45264 | K21: =PRODUCT(J8,J21) -> 2176.0547 | L21: 9 | M21: 0.01 | N21: =PRODUCT(L21,M21) -> 0.09 | O21: =PRODUCT(N21,C8) -> 0.1026 | P21: =SUM(C8,O21) -> 1.2426 | Q21: =PRODUCT(J8,P21) -> 1861.4148
B22: 9 | D22: int pomp/gustavo carrocero | F22: 12 | G22: 0.01 | H22: =PRODUCT(F22,G22) -> 0.12 | I22: =PRODUCT(H22,C6) -> 0.15564 | J22: =SUM(C6,I22) -> 1.45264 | K22: =PRODUCT(J8,J22) -> 2176.0547 | L22: 8 | M22: 0.01 | N22: =PRODUCT(L22,M22) -> 0.08 | O22: =PRODUCT(N22,C8) -> 0.0912 | P22: =SUM(C8,O22) -> 1.2312 | Q22: =PRODUCT(J8,P22) -> 1844.3376
B23: 10 | D23: DI LORENZO/alico | F23: 12 | G23: 0.01 | H23: =PRODUCT(F23,G23) -> 0.12 | I23: =PRODUCT(H23,C6) -> 0.15564 | J23: =SUM(C6,I23) -> 1.45264 | K23: =PRODUCT(J8,J23) -> 2176.0547 | L23: 9 | M23: 0.01 | N23: =PRODUCT(L23,M23) -> 0.09 | O23: =PRODUCT(N23,C8) -> 0.1026 | P23: =SUM(C8,O23) -> 1.2426 | Q23: =PRODUCT(J8,P23) -> 1861.4148
B24: 11 | D24: buromaik/calterm | F24: 7 | G24: 0.01 | H24: =PRODUCT(F24,G24) -> 0.07 | I24: =PRODUCT(H24,C6) -> 0.09079 | J24: =SUM(C6,I24) -> 1.38779 | K24: =PRODUCT(J8,J24) -> 2078.9094 | L24: 5 | M24: 0.01 | N24: =PRODUCT(L24,M24) -> 0.05 | O24: =PRODUCT(N24,C8) -> 0.057 | P24: =SUM(C8,O24) -> 1.197 | Q24: =PRODUCT(J8,P24) -> 1793.106
B25: 12 | D25: morelli/campana/proyectos/accetub | F25: 6 | G25: 0.01 | H25: =PRODUCT(F25,G25) -> 0.06 | I25: =PRODUCT(H25,C6) -> 0.07782 | J25: =SUM(C6,I25) -> 1.37482 | K25: =PRODUCT(J8,J25) -> 2059.4804 | L25: 1 | M25: 0.01 | N25: =PRODUCT(L25,M25) -> 0.01 | O25: =PRODUCT(N25,C8) -> 0.0114 | P25: =SUM(C8,O25) -> 1.1514 | Q25: =PRODUCT(J8,P25) -> 1724.7972
B26: 13 | D26: HORNOS DEL SUR/carbone/msequipment | F26: 8 | G26: 0.01 | H26: =PRODUCT(F26,G26) -> 0.08 | I26: =PRODUCT(H26,C6) -> 0.10376 | J26: =SUM(C6,I26) -> 1.40076 | K26: =PRODUCT(J8,J26) -> 2098.3385 | L26: 5 | M26: 0.01 | N26: =PRODUCT(L26,M26) -> 0.05 | O26: =PRODUCT(N26,C8) -> 0.057 | P26: =SUM(C8,O26) -> 1.197 | Q26: =PRODUCT(J8,P26) -> 1793.106
B27: 14 | D27: rominic/norberto | F27: 24 | G27: 0.01 | H27: =PRODUCT(F27,G27) -> 0.24 | I27: =PRODUCT(H27,C6) -> 0.31128 | J27: =SUM(C6,I27) -> 1.60828 | K27: =PRODUCT(J8,J27) -> 2409.2034 | L27: 20 | M27: 0.01 | N27: =PRODUCT(L27,M27) -> 0.2 | O27: =PRODUCT(N27,C8) -> 0.228 | P27: =SUM(C8,O27) -> 1.368 | Q27: =PRODUCT(J8,P27) -> 2049.264
B28: 15 | D28: GESTEC/ARLEM/FIGUE/denti | F28: 24 | G28: 0.01 | H28: =PRODUCT(F28,G28) -> 0.24 | I28: =PRODUCT(H28,C6) -> 0.31128 | J28: =SUM(C6,I28) -> 1.60828 | K28: =PRODUCT(J8,J28) -> 2409.2034 | L28: 20 | M28: 0.01 | N28: =PRODUCT(L28,M28) -> 0.2 | O28: =PRODUCT(N28,C8) -> 0.228 | P28: =SUM(C8,O28) -> 1.368 | Q28: =PRODUCT(J8,P28) -> 2049.264
B29: 16 | D29: TECTOOL / fioreti/buero | F29: 6 | G29: 0.01 | H29: =PRODUCT(F29,G29) -> 0.06 | I29: =PRODUCT(H29,C6) -> 0.07782 | J29: =SUM(C6,I29) -> 1.37482 | K29: =PRODUCT(J8,J29) -> 2059.4804 | L29: 1 | M29: 0.01 | N29: =PRODUCT(L29,M29) -> 0.01 | O29: =PRODUCT(N29,C8) -> 0.0114 | P29: =SUM(C8,O29) -> 1.1514 | Q29: =PRODUCT(J8,P29) -> 1724.7972
B30: 17 | D30: TALLERES NAVALES/burner/eqa | F30: 10 | G30: 0.01 | H30: =PRODUCT(F30,G30) -> 0.1 | I30: =PRODUCT(H30,C6) -> 0.1297 | J30: =SUM(C6,I30) -> 1.4267 | K30: =PRODUCT(J8,J30) -> 2137.1966 | L30: 8 | M30: 0.01 | N30: =PRODUCT(L30,M30) -> 0.08 | O30: =PRODUCT(N30,C8) -> 0.0912 | P30: =SUM(C8,O30) -> 1.2312 | Q30: =PRODUCT(J8,P30) -> 1844.3376
B31: 18 | D31: PROVIMAR/PUERTAS/CAMPANA/MULTILIFT//am carrocerias/megaces | F31: 10 | G31: 0.01 | H31: =PRODUCT(F31,G31) -> 0.1 | I31: =PRODUCT(H31,C6) -> 0.1297 | J31: =SUM(C6,I31) -> 1.4267 | K31: =PRODUCT(J8,J31) -> 2137.1966 | L31: 8 | M31: 0.01 | N31: =PRODUCT(L31,M31) -> 0.08 | O31: =PRODUCT(N31,C8) -> 0.0912 | P31: =SUM(C8,O31) -> 1.2312 | Q31: =PRODUCT(J8,P31) -> 1844.3376
B32: 19 | D32: BARRERA/ACEBA/diegez/fitnes | F32: 8 | G32: 0.01 | H32: =PRODUCT(F32,G32) -> 0.08 | I32: =PRODUCT(H32,C6) -> 0.10376 | J32: =SUM(C6,I32) -> 1.40076 | K32: =PRODUCT(J8,J32) -> 2098.3385 | L32: 4 | M32: 0.01 | N32: =PRODUCT(L32,M32) -> 0.04 | O32: =PRODUCT(N32,C8) -> 0.0456 | P32: =SUM(C8,O32) -> 1.1856 | Q32: =PRODUCT(J8,P32) -> 1776.0288
B33: 20 | D33: COVIC/acerotec/frachia/beta | F33: 12 | G33: 0.01 | H33: =PRODUCT(F33,G33) -> 0.12 | I33: =PRODUCT(H33,C6) -> 0.15564 | J33: =SUM(C6,I33) -> 1.45264 | K33: =PRODUCT(J8,J33) -> 2176.0547 | L33: 9 | M33: 0.01 | N33: =PRODUCT(L33,M33) -> 0.09 | O33: =PRODUCT(N33,C8) -> 0.1026 | P33: =SUM(C8,O33) -> 1.2426 | Q33: =PRODUCT(J8,P33) -> 1861.4148
B34: 21 | D34: cromwell/MET GUILLON | F34: 12 | G34: 0.01 | H34: =PRODUCT(F34,G34) -> 0.12 | I34: =PRODUCT(H34,C6) -> 0.15564 | J34: =SUM(C6,I34) -> 1.45264 | K34: =PRODUCT(J8,J34) -> 2176.0547 | L34: 9 | M34: 0.01 | N34: =PRODUCT(L34,M34) -> 0.09 | O34: =PRODUCT(N34,C8) -> 0.1026 | P34: =SUM(C8,O34) -> 1.2426 | Q34: =PRODUCT(J8,P34) -> 1861.4148
B35: 22 | D35: rodel/metic design/servitec | F35: 21 | G35: 0.01 | H35: =PRODUCT(F35,G35) -> 0.21 | I35: =PRODUCT(H35,C6) -> 0.27237 | J35: =SUM(C6,I35) -> 1.56937 | K35: =PRODUCT(J8,J35) -> 2350.9163 | L35: 18 | M35: 0.01 | N35: =PRODUCT(L35,M35) -> 0.18 | O35: =PRODUCT(N35,C8) -> 0.2052 | P35: =SUM(C8,O35) -> 1.3452 | Q35: =PRODUCT(J8,P35) -> 2015.1096
B36: 23 | D36: obregon/peope | F36: 8 | G36: 0.01 | H36: =PRODUCT(F36,G36) -> 0.08 | I36: =PRODUCT(H36,C6) -> 0.10376 | J36: =SUM(C6,I36) -> 1.40076 | K36: =PRODUCT(J8,J36) -> 2098.3385 | L36: 5 | M36: 0.01 | N36: =PRODUCT(L36,M36) -> 0.05 | O36: =PRODUCT(N36,C8) -> 0.057 | P36: =SUM(C8,O36) -> 1.197 | Q36: =PRODUCT(J8,P36) -> 1793.106
B37: 24 | D37: CARPINTERO/oximetal/met gh/rotofrance/calden/brauer | F37: 6 | G37: 0.01 | H37: =PRODUCT(F37,G37) -> 0.06 | I37: =PRODUCT(H37,C6) -> 0.07782 | J37: =SUM(C6,I37) -> 1.37482 | K37: =PRODUCT(J8,J37) -> 2059.4804 | L37: 1 | M37: 0.01 | N37: =PRODUCT(L37,M37) -> 0.01 | O37: =PRODUCT(N37,C8) -> 0.0114 | P37: =SUM(C8,O37) -> 1.1514 | Q37: =PRODUCT(J8,P37) -> 1724.7972
B38: 25 | D38: HIERGATH/GALARZA | F38: 10 | G38: 0.01 | H38: =PRODUCT(F38,G38) -> 0.1 | I38: =PRODUCT(H38,C6) -> 0.1297 | J38: =SUM(C6,I38) -> 1.4267 | K38: =PRODUCT(J8,J38) -> 2137.1966 | L38: 9 | M38: 0.01 | N38: =PRODUCT(L38,M38) -> 0.09 | O38: =PRODUCT(N38,C8) -> 0.1026 | P38: =SUM(C8,O38) -> 1.2426 | Q38: =PRODUCT(J8,P38) -> 1861.4148
B39: 26 | D39: SARRO/lumac/rimauro | F39: 12 | G39: 0.01 | H39: =PRODUCT(F39,G39) -> 0.12 | I39: =PRODUCT(H39,C6) -> 0.15564 | J39: =SUM(C6,I39) -> 1.45264 | K39: =PRODUCT(J8,J39) -> 2176.0547 | L39: 10 | M39: 0.01 | N39: =PRODUCT(L39,M39) -> 0.1 | O39: =PRODUCT(N39,C8) -> 0.114 | P39: =SUM(C8,O39) -> 1.254 | Q39: =PRODUCT(J8,P39) -> 1878.492
B40: 27 | D40: RADICE/DODERO/secaire | F40: 12 | G40: 0.01 | H40: =PRODUCT(F40,G40) -> 0.12 | I40: =PRODUCT(H40,C6) -> 0.15564 | J40: =SUM(C6,I40) -> 1.45264 | K40: =PRODUCT(J8,J40) -> 2176.0547 | L40: 5 | M40: 0.01 | N40: =PRODUCT(L40,M40) -> 0.05 | O40: =PRODUCT(N40,C8) -> 0.057 | P40: =SUM(C8,O40) -> 1.197 | Q40: =PRODUCT(J8,P40) -> 1793.106
B41: 28 | D41: ACEREC/escapes/solomita | F41: 8 | G41: 0.01 | H41: =PRODUCT(F41,G41) -> 0.08 | I41: =PRODUCT(H41,C6) -> 0.10376 | J41: =SUM(C6,I41) -> 1.40076 | K41: =PRODUCT(J8,J41) -> 2098.3385 | L41: 6 | M41: 0.01 | N41: =PRODUCT(L41,M41) -> 0.06 | O41: =PRODUCT(N41,C8) -> 0.0684 | P41: =SUM(C8,O41) -> 1.2084 | Q41: =PRODUCT(J8,P41) -> 1810.1832
B42: 29 | D42: binetti/titanium/carlos | F42: 8 | G42: 0.01 | H42: =PRODUCT(F42,G42) -> 0.08 | I42: =PRODUCT(H42,C6) -> 0.10376 | J42: =SUM(C6,I42) -> 1.40076 | K42: =PRODUCT(J8,J42) -> 2098.3385 | L42: 5 | M42: 0.01 | N42: =PRODUCT(L42,M42) -> 0.05 | O42: =PRODUCT(N42,C8) -> 0.057 | P42: =SUM(C8,O42) -> 1.197 | Q42: =PRODUCT(J8,P42) -> 1793.106
B43: 30 | D43: CUATRO ASES/secaire/petenelo/maresca | F43: 8 | G43: 0.01 | H43: =PRODUCT(F43,G43) -> 0.08 | I43: =PRODUCT(H43,C6) -> 0.10376 | J43: =SUM(C6,I43) -> 1.40076 | K43: =PRODUCT(J8,J43) -> 2098.3385 | L43: 5 | M43: 0.01 | N43: =PRODUCT(L43,M43) -> 0.05 | O43: =PRODUCT(N43,C8) -> 0.057 | P43: =SUM(C8,O43) -> 1.197 | Q43: =PRODUCT(J8,P43) -> 1793.106
B44: 31 | D44: colo | F44: 6 | G44: 0.01 | H44: =PRODUCT(F44,G44) -> 0.06 | I44: =PRODUCT(H44,C6) -> 0.07782 | J44: =SUM(C6,I44) -> 1.37482 | K44: =PRODUCT(J8,J44) -> 2059.4804 | L44: 2 | M44: 0.01 | N44: =PRODUCT(L44,M44) -> 0.02 | O44: =PRODUCT(N44,C8) -> 0.0228 | P44: =SUM(C8,O44) -> 1.1628 | Q44: =PRODUCT(J8,P44) -> 1741.8744
B45: 32 | D45: DALMA/fornari | F45: 12 | G45: 0.01 | H45: =PRODUCT(F45,G45) -> 0.12 | I45: =PRODUCT(H45,C6) -> 0.15564 | J45: =SUM(C6,I45) -> 1.45264 | K45: =PRODUCT(J8,J45) -> 2176.0547 | L45: 9 | M45: 0.01 | N45: =PRODUCT(L45,M45) -> 0.09 | O45: =PRODUCT(N45,C8) -> 0.1026 | P45: =SUM(C8,O45) -> 1.2426 | Q45: =PRODUCT(J8,P45) -> 1861.4148
B46: 33 | D46: ITEXA | F46: 8 | G46: 0.01 | H46: =PRODUCT(F46,G46) -> 0.08 | I46: =PRODUCT(H46,C6) -> 0.10376 | J46: =SUM(C6,I46) -> 1.40076 | K46: =PRODUCT(J8,J46) -> 2098.3385 | L46: 5 | M46: 0.01 | N46: =PRODUCT(L46,M46) -> 0.05 | O46: =PRODUCT(N46,C8) -> 0.057 | P46: =SUM(C8,O46) -> 1.197 | Q46: =PRODUCT(J8,P46) -> 1793.106
B47: 34 | D47: CB ACCESORIOS/fursan/casasco | F47: 8 | G47: 0.01 | H47: =PRODUCT(F47,G47) -> 0.08 | I47: =PRODUCT(H47,C6) -> 0.10376 | J47: =SUM(C6,I47) -> 1.40076 | K47: =PRODUCT(J8,J47) -> 2098.3385 | L47: 5 | M47: 0.01 | N47: =PRODUCT(L47,M47) -> 0.05 | O47: =PRODUCT(N47,C8) -> 0.057 | P47: =SUM(C8,O47) -> 1.197 | Q47: =PRODUCT(J8,P47) -> 1793.106
B48: 35 | D48: BRIMPEX | F48: 14 | G48: 0.01 | H48: =PRODUCT(F48,G48) -> 0.14 | I48: =PRODUCT(H48,C6) -> 0.18158 | J48: =SUM(C6,I48) -> 1.47858 | K48: =PRODUCT(J8,J48) -> 2214.9128 | L48: 12 | M48: 0.01 | N48: =PRODUCT(L48,M48) -> 0.12 | O48: =PRODUCT(N48,C8) -> 0.1368 | P48: =SUM(C8,O48) -> 1.2768 | Q48: =PRODUCT(J8,P48) -> 1912.6464
...

Sheet 1
D2: =PROPER(INICIO!D14) -> Tato/Rolando/Alpes/Javier/Bassaro/El Roble
B4: LISTA DE PRECIOS EN PESOS
B5: DD | C5: 1000 | D5: 1220 | E5: 1500 | G5: NEGRA | H5: 1000 | I5: 1245 | J5: 1500
B6: 16 | C6: =SUM(C16*0.07)+C16 -> 2245.2222 | D6: =SUM(C16*0.04)+C16 -> 2182.272 | E6: =SUM(C16*0.04)+C16 -> 2182.272 | G6: 1.6 | H6: =SUM(H16*0.14)+H16 -> 2044.1408 | I6: XXX | J6: XXX
B7: 18 | C7: =SUM(C16*0.07)+C16 -> 2245.2222 | D7: =SUM(C16*0.04)+C16 -> 2182.272 | E7: =SUM(C16*0.04)+C16 -> 2182.272 | G7: 2 | H7: =SUM(H16*0.143)+H16 -> 2049.5202 | I7: =SUM(H16*0.11)+H16 -> 1990.3477 | J7: XXX
B8: 12,14 y 20 | C8: =SUM(C16*0.08)+C16 -> 2266.2056 | D8: =SUM(C16*0.05)+C16 -> 2203.2554 | E8: =SUM(C16*0.05)+C16 -> 2203.2554 | G8: 2.5 | H8: =SUM(H16*0.12)+H16 -> 2008.2787 | I8: =SUM(H16*0.09)+H16 -> 1954.4855 | J8: XXX
B9: 22 | C9: =SUM(C16*0.1)+C16 -> 2308.1723 | D9: =SUM(C16*0.07)+C16 -> 2245.2222 | E9: =SUM(C16*0.07)+C16 -> 2245.2222 | G9: 3.17 | H9: =SUM(H16*0.11)+H16 -> 1990.3477 | I9: =SUM(H16*0.08)+H16 -> 1936.5545 | J9: =SUM(H16*0.08)+H16 -> 1936.5545
B10: 0.65 | C10: =SUM(C16*0.12)+C16 -> 2350.1391 | D10: =SUM(C16*0.09)+C16 -> 2287.1889 | E10: XXX | G10: 4,75 Y 4.00 | H10: =SUM(H16*0.1)+H16 -> 1972.4166 | I10: =SUM(H16*0.07+H16) -> 1918.6234 | J10: =SUM(H16*0.07)+H16 -> 1918.6234
B11: 24 | C11: =SUM(C16*0.16)+C16 -> 2434.0726 | D11: =SUM(C16*0.13)+C16 -> 2371.1225 | E11: XXX | G11: 6.35 | H11: =SUM(H16*0.11)+H16 -> 1990.3477 | I11: =SUM(H16*0.08)+H16 -> 1936.5545 | J11: =SUM(H16*0.08)+H16 -> 1936.5545
B12: 26 | C12: =SUM(C16*0.2)+C16 -> 2518.0062 | D12: =SUM(C16*0.15)+C16 -> 2413.0893 | E12: XXX | G12: 8 | H12: =SUM(H16*0.11)+H16 -> 1990.3477 | I12: =SUM(H16*0.08)+H16 -> 1936.5545 | J12: =SUM(H16*0.08)+H16 -> 1936.5545
B13: 27 | C13: =SUM(C16*0.26)+C16 -> 2643.9065 | D13: XXX | E13: XXX | G13: 9.52 | H13: =SUM(H16*0.12)+H16 -> 2008.2787 | I13: =SUM(H16*0.09)+H16 -> 1954.4855 | J13: =SUM(H16*0.09)+H16 -> 1954.4855
B14: 30 | C14: =SUM(C16*0.32)+C16 -> 2769.8068 | D14: XXX | E14: XXX | G14: 12.7 | H14: =SUM(H16*0.12)+H16 -> 2008.2787 | I14: =SUM(H16*0.09)+H16 -> 1954.4855 | J14: =SUM(H16*0.09)+H16 -> 1954.4855
B16: BASE | C16: =SUM(INICIO!K14) -> 2098.3385 | G16: BASE | H16: =SUM(INICIO!Q14) -> 1793.106 | J16: herrero 10%
J17: pagola 10%
B18: 3.17 | C18: 1245 | D18: S/MEL | E18: =SUM(I9*0.1)+I9 -> 2130.2099 | I18: CALIDAD | J18: el roble 10% | K18: micro -12
B19: 4.75 | C19: 1500 | D19: S/MEL | E19: =SUM(J10*0.1)+J10 -> 2110.4858 | I19: ANCHO | J19: tato10%
B20: 6.35 | C20: 1500 | D20: S/MEL | E20: =SUM(J11*0.1)+J11 -> 2130.2099 | I20: ESPESOR
B22: LISTA DE PRECIOS EN DÓLARES
B23: DD | C23: 1000 | D23: 1220 | E23: 1500 | G23: NEGRA | H23: 1000 | I23: 1245 | J23: 1500
B24: 16 | C24: =SUM(C34*0.07)+C34 -> 1.4988132 | D24: =SUM(C34*0.04)+C34 -> 1.4567904 | E24: =SUM(C34*0.04)+C34 -> 1.4567904 | G24: 1.6 | H24: =SUM(H34*0.2)+H34 -> 1.4364 | I24: XXX | J24: XXX
B25: 18 | C25: =SUM(C34*0.07)+C34 -> 1.4988132 | D25: =SUM(C34*0.04)+C34 -> 1.4567904 | E25: =SUM(C34*0.04)+C34 -> 1.4567904 | G25: 2 | H25: =SUM(H34*0.14)+H34 -> 1.36458 | I25: =SUM(H34*0.11)+H34 -> 1.32867 | J25: XXX
B26: 12,14 y 20 | C26: =SUM(C34*0.08)+C34 -> 1.5128208 | D26: =SUM(C34*0.05)+C34 -> 1.470798 | E26: =SUM(C34*0.05)+C34 -> 1.470798 | G26: 2.5 | H26: =SUM(H34*0.12)+H34 -> 1.34064 | I26: =SUM(H34*0.09)+H34 -> 1.30473 | J26: XXX
B27: 22 | C27: =SUM(C34*0.1)+C34 -> 1.540836 | D27: =SUM(C34*0.07)+C34 -> 1.4988132 | E27: =SUM(C34*0.07)+C34 -> 1.4988132 | G27: 3.17 | H27: =SUM(H34*0.11)+H34 -> 1.32867 | I27: =SUM(H34*0.08)+H34 -> 1.29276 | J27: =SUM(H34*0.08)+H34 -> 1.29276
B28: 0.65 | C28: =SUM(C34*0.12)+C34 -> 1.5688512 | D28: =SUM(C34*0.09)+C34 -> 1.5268284 | E28: XXX | G28: 4,75 Y 4.00 | H28: =SUM(H34*0.1)+H34 -> 1.3167 | I28: =SUM(H34*0.07+H34) -> 1.28079 | J28: =SUM(H34*0.07)+H34 -> 1.28079
B29: 24 | C29: =SUM(C34*0.16)+C34 -> 1.6248816 | D29: =SUM(C34*0.13)+C34 -> 1.5828588 | E29: XXX | G29: 6.35 | H29: =SUM(H34*0.11)+H34 -> 1.32867 | I29: =SUM(H34*0.08)+H34 -> 1.29276 | J29: =SUM(H34*0.08)+H34 -> 1.29276
B30: 26 | C30: =SUM(C34*0.2)+C34 -> 1.680912 | D30: =SUM(C34*0.15)+C34 -> 1.610874 | E30: XXX | G30: 8 | H30: =SUM(H34*0.11)+H34 -> 1.32867 | I30: =SUM(H34*0.08)+H34 -> 1.29276 | J30: =SUM(H34*0.08)+H34 -> 1.29276
B31: 27 | C31: =SUM(C34*0.26)+C34 -> 1.7649576 | D31: XXX | E31: XXX | G31: 9.52 | H31: =SUM(H34*0.12)+H34 -> 1.34064 | I31: =SUM(H34*0.09)+H34 -> 1.30473 | J31: =SUM(H34*0.09)+H34 -> 1.30473
B32: 30 | C32: =SUM(C34*0.32)+C34 -> 1.8490032 | D32: XXX | E32: XXX | G32: 12.7 | H32: =SUM(H34*0.12)+H34 -> 1.34064 | I32: =SUM(H34*0.09)+H34 -> 1.30473 | J32: =SUM(H34*0.09)+H34 -> 1.30473
B34: BASE | C34: =SUM(INICIO!J14) -> 1.40076 | G34: BASE | H34: =SUM(INICIO!P14) -> 1.197
B36: 3.17 | C36: 1245 | D36: S/MEL | E36: =SUM(I27*0.1)+I27 -> 1.422036 | I36: CALIDAD
B37: 4.75 | C37: 1500 | D37: S/MEL | E37: =SUM(J28*0.1)+J28 -> 1.408869 | I37: ANCHO
B38: 6.35 | C38: 1500 | D38: S/MEL | E38: =SUM(J29*0.1)+J29 -> 1.422036 | I38: ESPESOR
B41: galv | C41: 1000 | D41: 1220
B42: 16 14
B43: 18
B44: 20
B45: 22
B46: 24
B47: 25
B48: 26

Sheet 2
B2: CLIENTE: | D2: =PROPER(INICIO!D15) -> Martinez/Pretocom/Parrillas Omar/Gillio
B4: LISTA DE PRECIOS EN PESOS
B5: DD | C5: 1000 | D5: 1220 | E5: 1500 | G5: NEGRA | H5: 1000 | I5: 1245 | J5: 1500
B6: 16 | C6: =SUM(C16*0.07)+C16 -> 2245.2222 | D6: =SUM(C16*0.04)+C16 -> 2182.272 | E6: =SUM(C16*0.04)+C16 -> 2182.272 | G6: 1.6 | H6: XXX | I6: XXX | J6: XXX
B7: 18 | C7: =SUM(C16*0.07)+C16 -> 2245.2222 | D7: =SUM(C16*0.04)+C16 -> 2182.272 | E7: =SUM(C16*0.04)+C16 -> 2182.272 | G7: 2 | H7: =SUM(H16*0.14)+H16 -> 2044.1408 | I7: =SUM(H16*0.11)+H16 -> 1990.3477 | J7: XXX
B8: 12,14 y 20 | C8: =SUM(C16*0.08)+C16 -> 2266.2056 | D8: =SUM(C16*0.05)+C16 -> 2203.2554 | E8: =SUM(C16*0.05)+C16 -> 2203.2554 | G8: 2.5 | H8: =SUM(H16*0.12)+H16 -> 2008.2787 | I8: =SUM(H16*0.09)+H16 -> 1954.4855 | J8: XXX
B9: 22 | C9: =SUM(C16*0.1)+C16 -> 2308.1723 | D9: =SUM(C16*0.07)+C16 -> 2245.2222 | E9: =SUM(C16*0.07)+C16 -> 2245.2222 | G9: 3.17 | H9: =SUM(H16*0.11)+H16 -> 1990.3477 | I9: =SUM(H16*0.08)+H16 -> 1936.5545 | J9: =SUM(H16*0.08)+H16 -> 1936.5545
B10: 0.65 | C10: =SUM(C16*0.12)+C16 -> 2350.1391 | D10: =SUM(C16*0.09)+C16 -> 2287.1889 | E10: XXX | G10: 4,75 Y 4.00 | H10: =SUM(H16*0.1)+H16 -> 1972.4166 | I10: =SUM(H16*0.07+H16) -> 1918.6234 | J10: =SUM(H16*0.07)+H16 -> 1918.6234
B11: 24 | C11: =SUM(C16*0.16)+C16 -> 2434.0726 | D11: =SUM(C16*0.13)+C16 -> 2371.1225 | E11: XXX | G11: 6.35 | H11: =SUM(H16*0.11)+H16 -> 1990.3477 | I11: =SUM(H16*0.08)+H16 -> 1936.5545 | J11: =SUM(H16*0.08)+H16 -> 1936.5545
B12: 26 | C12: =SUM(C16*0.2)+C16 -> 2518.0062 | D12: =SUM(C16*0.15)+C16 -> 2413.0893 | E12: XXX | G12: 8 | H12: =SUM(H16*0.11)+H16 -> 1990.3477 | I12: =SUM(H16*0.08)+H16 -> 1936.5545 | J12: =SUM(H16*0.08)+H16 -> 1936.5545
B13: 27 | C13: =SUM(C16*0.26)+C16 -> 2643.9065 | D13: XXX | E13: XXX | G13: 9.52 | H13: =SUM(H16*0.12)+H16 -> 2008.2787 | I13: =SUM(H16*0.09)+H16 -> 1954.4855 | J13: =SUM(H16*0.1)+H16 -> 1972.4166 | L13: brauer8
B14: 30 | C14: =SUM(C16*0.32)+C16 -> 2769.8068 | D14: XXX | E14: XXX | G14: 12.7 | H14: =SUM(H16*0.12)+H16 -> 2008.2787 | I14: =SUM(H16*0.09)+H16 -> 1954.4855 | J14: =SUM(H16*0.1)+H16 -> 1972.4166
B16: BASE | C16: =SUM(INICIO!K15) -> 2098.3385 | G16: BASE | H16: =SUM(INICIO!Q15) -> 1793.106 | I16: dec 2,6 | J16: 1.16 | K16: 45386
J17: elbio -6% | K17: lonc 8%
B18: 3.17 | C18: 1245 | D18: S/MEL | E18: =SUM(I9*0.1)+I9 -> 2130.2099 | I18: CALIDAD | J18: cal 1/4 3/16-12
B19: 4.75 | C19: 1500 | D19: S/MEL | E19: =SUM(J10*0.1)+J10 -> 2110.4858 | I19: ANCHO
B20: 6.35 | C20: 1500 | D20: S/MEL | E20: =SUM(J11*0.1)+J11 -> 2130.2099 | I20: ESPESOR
B22: LISTA DE PRECIOS EN DÓLARES
B23: DD | C23: 1000 | D23: 1220 | E23: 1500 | G23: NEGRA | H23: 1000 | I23: 1245 | J23: 1500
B24: 16 | C24: =SUM(C34*0.07)+C34 -> 1.4988132 | D24: =SUM(C34*0.04)+C34 -> 1.4567904 | E24: =SUM(C34*0.04)+C34 -> 1.4567904 | G24: 1.6 | H24: XXX | I24: XXX | J24: XXX
B25: 18 | C25: =SUM(C34*0.07)+C34 -> 1.4988132 | D25: =SUM(C34*0.04)+C34 -> 1.4567904 | E25: =SUM(C34*0.04)+C34 -> 1.4567904 | G25: 2 | H25: =SUM(H34*0.14)+H34 -> 1.36458 | I25: =SUM(H34*0.11)+H34 -> 1.32867 | J25: XXX
B26: 12,14 y 20 | C26: =SUM(C34*0.08)+C34 -> 1.5128208 | D26: =SUM(C34*0.05)+C34 -> 1.470798 | E26: =SUM(C34*0.05)+C34 -> 1.470798 | G26: 2.5 | H26: =SUM(H34*0.12)+H34 -> 1.34064 | I26: =SUM(H34*0.09)+H34 -> 1.30473 | J26: XXX
B27: 22 | C27: =SUM(C34*0.1)+C34 -> 1.540836 | D27: =SUM(C34*0.07)+C34 -> 1.4988132 | E27: =SUM(C34*0.07)+C34 -> 1.4988132 | G27: 3.17 | H27: =SUM(H34*0.11)+H34 -> 1.32867 | I27: =SUM(H34*0.08)+H34 -> 1.29276 | J27: =SUM(H34*0.08)+H34 -> 1.29276
B28: 0.65 | C28: =SUM(C34*0.12)+C34 -> 1.5688512 | D28: =SUM(C34*0.09)+C34 -> 1.5268284 | E28: XXX | G28: 4,75 Y 4.00 | H28: =SUM(H34*0.1)+H34 -> 1.3167 | I28: =SUM(H34*0.07+H34) -> 1.28079 | J28: =SUM(H34*0.07)+H34 -> 1.28079
B29: 24 | C29: =SUM(C34*0.16)+C34 -> 1.6248816 | D29: =SUM(C34*0.13)+C34 -> 1.5828588 | E29: XXX | G29: 6.35 | H29: =SUM(H34*0.11)+H34 -> 1.32867 | I29: =SUM(H34*0.08)+H34 -> 1.29276 | J29: =SUM(H34*0.08)+H34 -> 1.29276
B30: 26 | C30: =SUM(C34*0.2)+C34 -> 1.680912 | D30: =SUM(C34*0.15)+C34 -> 1.610874 | E30: XXX | G30: 8 | H30: =SUM(H34*0.11)+H34 -> 1.32867 | I30: =SUM(H34*0.08)+H34 -> 1.29276 | J30: =SUM(H34*0.08)+H34 -> 1.29276
B31: 27 | C31: =SUM(C34*0.26)+C34 -> 1.7649576 | D31: XXX | E31: XXX | G31: 9.52 | H31: =SUM(H34*0.12)+H34 -> 1.34064 | I31: =SUM(H34*0.09)+H34 -> 1.30473 | J31: =SUM(H34*0.09)+H34 -> 1.30473
B32: 30 | C32: =SUM(C34*0.32)+C34 -> 1.8490032 | D32: XXX | E32: XXX | G32: 12.7 | H32: =SUM(H34*0.12)+H34 -> 1.34064 | I32: =SUM(H34*0.09)+H34 -> 1.30473 | J32: =SUM(H34*0.09)+H34 -> 1.30473
B34: BASE | C34: =SUM(INICIO!J15) -> 1.40076 | G34: BASE | H34: =SUM(INICIO!P15) -> 1.197
B36: 3.17 | C36: 1245 | D36: S/MEL | E36: =SUM(I27*0.1)+I27 -> 1.422036 | I36: CALIDAD
B37: 4.75 | C37: 1500 | D37: S/MEL | E37: =SUM(J28*0.1)+J28 -> 1.408869 | I37: ANCHO
B38: 6.35 | C38: 1500 | D38: S/MEL | E38: =SUM(J29*0.1)+J29 -> 1.422036 | I38: ESPESOR
B42: caño | C42: elbio
B43: 40x60x2 | C43: 0
B44: 40x60x1,6
C45: =SUM(C53*0.08)+C53 -> 0

Sheet 3
B2: CLIENTE: | D2: =PROPER(INICIO!D16) -> Megacer/Esimet/Ravi/Sonoflex
B4: LISTA DE PRECIOS EN PESOS
B5: DD | C5: 1000 | D5: 1220 | E5: 1500 | G5: NEGRA | H5: 1000 | I5: 1245 | J5: 1500
B6: 16 | C6: =SUM(C16*0.07)+C16 -> 2390.7458 | D6: =SUM(C16*0.04)+C16 -> 2323.7156 | E6: =SUM(C16*0.04)+C16 -> 2323.7156 | G6: 1.6 | H6: XXX | I6: XXX | J6: XXX
B7: 18 | C7: =SUM(C16*0.07)+C16 -> 2390.7458 | D7: =SUM(C16*0.04)+C16 -> 2323.7156 | E7: =SUM(C16*0.04)+C16 -> 2323.7156 | G7: 2 | H7: =SUM(H16*0.14)+H16 -> 2141.4809 | I7: =SUM(H16*0.11)+H16 -> 2085.1261 | J7: XXX
B8: 12,14 y 20 | C8: =SUM(C16*0.08)+C16 -> 2413.0893 | D8: =SUM(C16*0.05)+C16 -> 2346.059 | E8: =SUM(C16*0.05)+C16 -> 2346.059 | G8: 2.5 | H8: =SUM(H16*0.12)+H16 -> 2103.911 | I8: =SUM(H16*0.09)+H16 -> 2047.5563 | J8: XXX
B9: 22 | C9: =SUM(C16*0.1)+C16 -> 2457.7761 | D9: =SUM(C16*0.07)+C16 -> 2390.7458 | E9: =SUM(C16*0.07)+C16 -> 2390.7458 | G9: 3.17 | H9: =SUM(H16*0.11)+H16 -> 2085.1261 | I9: =SUM(H16*0.08)+H16 -> 2028.7714 | J9: =SUM(H16*0.08)+H16 -> 2028.7714
B10: 0.65 | C10: =SUM(C16*0.12)+C16 -> 2502.4629 | D10: =SUM(C16*0.09)+C16 -> 2435.4327 | E10: XXX | G10: 4,75 Y 4.00 | H10: =SUM(H16*0.1)+H16 -> 2066.3412 | I10: =SUM(H16*0.07+H16) -> 2009.9864 | J10: =SUM(H16*0.07)+H16 -> 2009.9864
B11: 24 | C11: =SUM(C16*0.16)+C16 -> 2591.8366 | D11: =SUM(C16*0.13)+C16 -> 2524.8063 | E11: XXX | G11: 6.35 | H11: =SUM(H16*0.11)+H16 -> 2085.1261 | I11: =SUM(H16*0.08)+H16 -> 2028.7714 | J11: =SUM(H16*0.08)+H16 -> 2028.7714
B12: 26 | C12: =SUM(C16*0.2)+C16 -> 2681.2103 | D12: =SUM(C16*0.15)+C16 -> 2569.4932 | E12: XXX | G12: 8 | H12: =SUM(H16*0.11)+H16 -> 2085.1261 | I12: =SUM(H16*0.08)+H16 -> 2028.7714 | J12: =SUM(H16*0.08)+H16 -> 2028.7714
B13: 27 | C13: =SUM(C16*0.26)+C16 -> 2815.2708 | D13: XXX | E13: XXX | G13: 9.52 | H13: =SUM(H16*0.12)+H16 -> 2103.911 | I13: =SUM(H16*0.09)+H16 -> 2047.5563 | J13: =SUM(H16*0.09)+H16 -> 2047.5563
B14: 30 | C14: =SUM(C16*0.32)+C16 -> 2949.3313 | D14: XXX | E14: XXX | G14: 12.7 | H14: =SUM(H16*0.12)+H16 -> 2103.911 | I14: =SUM(H16*0.09)+H16 -> 2047.5563 | J14: =SUM(H16*0.09)+H16 -> 2047.5563
B16: BASE | C16: =SUM(INICIO!K16) -> 2234.3419 | G16: BASE | H16: =SUM(INICIO!Q16) -> 1878.492
B18: 3.17 | C18: 1245 | D18: S/MEL | E18: =SUM(I9*0.1)+I9 -> 2231.6485 | I18: CALIDAD
B19: 4.75 | C19: 1500 | D19: S/MEL | E19: =SUM(J10*0.1)+J10 -> 2210.9851 | I19: ANCHO
B20: 6.35 | C20: 1500 | D20: S/MEL | E20: =SUM(J11*0.1)+J11 -> 2231.6485 | I20: ESPESOR
B22: LISTA DE PRECIOS EN DÓLARES
B23: DD | C23: 1000 | D23: 1220 | E23: 1500 | G23: NEGRA | H23: 1000 | I23: 1245 | J23: 1500
B24: 16 | C24: =SUM(C34*0.07)+C34 -> 1.5959585 | D24: =SUM(C34*0.04)+C34 -> 1.551212 | E24: =SUM(C34*0.04)+C34 -> 1.551212 | G24: 1.6 | H24: XXX | I24: XXX | J24: XXX
B25: 18 | C25: =SUM(C34*0.07)+C34 -> 1.5959585 | D25: =SUM(C34*0.04)+C34 -> 1.551212 | E25: =SUM(C34*0.04)+C34 -> 1.551212 | G25: 2 | H25: =SUM(H34*0.14)+H34 -> 1.42956 | I25: =SUM(H34*0.11)+H34 -> 1.39194 | J25: XXX
B26: 12,14 y 20 | C26: =SUM(C34*0.08)+C34 -> 1.610874 | D26: =SUM(C34*0.05)+C34 -> 1.5661275 | E26: =SUM(C34*0.05)+C34 -> 1.5661275 | G26: 2.5 | H26: =SUM(H34*0.12)+H34 -> 1.40448 | I26: =SUM(H34*0.09)+H34 -> 1.36686 | J26: XXX
B27: 22 | C27: =SUM(C34*0.1)+C34 -> 1.640705 | D27: =SUM(C34*0.07)+C34 -> 1.5959585 | E27: =SUM(C34*0.07)+C34 -> 1.5959585 | G27: 3.17 | H27: =SUM(H34*0.11)+H34 -> 1.39194 | I27: =SUM(H34*0.08)+H34 -> 1.35432 | J27: =SUM(H34*0.08)+H34 -> 1.35432
B28: 0.65 | C28: =SUM(C34*0.12)+C34 -> 1.670536 | D28: =SUM(C34*0.09)+C34 -> 1.6257895 | E28: XXX | G28: 4,75 Y 4.00 | H28: =SUM(H34*0.1)+H34 -> 1.3794 | I28: =SUM(H34*0.07+H34) -> 1.34178 | J28: =SUM(H34*0.07)+H34 -> 1.34178
B29: 24 | C29: =SUM(C34*0.16)+C34 -> 1.730198 | D29: =SUM(C34*0.13)+C34 -> 1.6854515 | E29: XXX | G29: 6.35 | H29: =SUM(H34*0.11)+H34 -> 1.39194 | I29: =SUM(H34*0.08)+H34 -> 1.35432 | J29: =SUM(H34*0.08)+H34 -> 1.35432
B30: 26 | C30: =SUM(C34*0.2)+C34 -> 1.78986 | D30: =SUM(C34*0.15)+C34 -> 1.7152825 | E30: XXX | G30: 8 | H30: =SUM(H34*0.11)+H34 -> 1.39194 | I30: =SUM(H34*0.08)+H34 -> 1.35432 | J30: =SUM(H34*0.08)+H34 -> 1.35432
B31: 27 | C31: =SUM(C34*0.26)+C34 -> 1.879353 | D31: XXX | E31: XXX | G31: 9.52 | H31: =SUM(H34*0.12)+H34 -> 1.40448 | I31: =SUM(H34*0.09)+H34 -> 1.36686 | J31: =SUM(H34*0.09)+H34 -> 1.36686
B32: 30 | C32: =SUM(C34*0.32)+C34 -> 1.968846 | D32: XXX | E32: XXX | G32: 12.7 | H32: =SUM(H34*0.12)+H34 -> 1.40448 | I32: =SUM(H34*0.09)+H34 -> 1.36686 | J32: =SUM(H34*0.09)+H34 -> 1.36686
B34: BASE | C34: =SUM(INICIO!J16) -> 1.49155 | G34: BASE | H34: =SUM(INICIO!P16) -> 1.254
B36: 3.17 | C36: 1245 | D36: S/MEL | E36: =SUM(I27*0.1)+I27 -> 1.489752 | I36: CALIDAD
B37: 4.75 | C37: 1500 | D37: S/MEL | E37: =SUM(J28*0.1)+J28 -> 1.475958 | I37: ANCHO
B38: 6.35 | C38: 1500 | D38: S/MEL | E38: =SUM(J29*0.1)+J29 -> 1.489752 | I38: ESPESOR
B43: galv | C43: 1000 | D43: 1220
B44: 16 14
B45: 18
B46: 20
B47: 22
B48: 24
B49: 25
B50: 26

Sheet 4
B2: CLIENTE: | D2: =PROPER(INICIO!D17) -> Fabrical
B4: LISTA DE PRECIOS EN PESOS
B5: DD | C5: 1000 | D5: 1220 | E5: 1500 | G5: NEGRA | H5: 1000 | I5: 1245 | J5: 1500
B6: 16 | C6: =SUM(C16*0.07)+C16 -> 2328.3786 | D6: =SUM(C16*0.04)+C16 -> 2263.0969 | E6: =SUM(C16*0.04)+C16 -> 2263.0969 | G6: 1.6 | H6: XXX | I6: XXX | J6: XXX
B7: 18 | C7: =SUM(C16*0.07)+C16 -> 2328.3786 | D7: =SUM(C16*0.04)+C16 -> 2263.0969 | E7: =SUM(C16*0.04)+C16 -> 2263.0969 | G7: 2 | H7: =SUM(H16*0.14)+H16 -> 2083.0769 | I7: =SUM(H16*0.11)+H16 -> 2028.259 | J7: XXX
B8: 12,14 y 20 | C8: =SUM(C16*0.08)+C16 -> 2350.1391 | D8: =SUM(C16*0.05)+C16 -> 2284.8575 | E8: =SUM(C16*0.05)+C16 -> 2284.8575 | G8: 2.5 | H8: =SUM(H16*0.12)+H16 -> 2046.5316 | I8: =SUM(H16*0.09)+H16 -> 1991.7138 | J8: XXX
B9: 22 | C9: =SUM(C16*0.1)+C16 -> 2393.6602 | D9: =SUM(C16*0.07)+C16 -> 2328.3786 | E9: =SUM(C16*0.07)+C16 -> 2328.3786 | G9: 3.17 | H9: =SUM(H16*0.11)+H16 -> 2028.259 | I9: =SUM(H16*0.08)+H16 -> 1973.4412 | J9: =SUM(H16*0.08)+H16 -> 1973.4412
B10: 0.65 | C10: =SUM(C16*0.12)+C16 -> 2437.1813 | D10: =SUM(C16*0.09)+C16 -> 2371.8996 | E10: XXX | G10: 4,75 Y 4.00 | H10: =SUM(H16*0.11)+H16 -> 2028.259 | I10: =SUM(H16*0.08+H16) -> 1973.4412 | J10: =SUM(H16*0.08)+H16 -> 1973.4412
B11: 24 | C11: =SUM(C16*0.16)+C16 -> 2524.2235 | D11: =SUM(C16*0.13)+C16 -> 2458.9418 | E11: XXX | G11: 6.35 | H11: =SUM(H16*0.11)+H16 -> 2028.259 | I11: =SUM(H16*0.08)+H16 -> 1973.4412 | J11: =SUM(H16*0.08)+H16 -> 1973.4412
B12: 26 | C12: =SUM(C16*0.2)+C16 -> 2611.2657 | D12: =SUM(C16*0.15)+C16 -> 2502.4629 | E12: XXX | G12: 8 | H12: =SUM(H16*0.11)+H16 -> 2028.259 | I12: =SUM(H16*0.08)+H16 -> 1973.4412 | J12: =SUM(H16*0.08)+H16 -> 1973.4412
B13: 27 | C13: =SUM(C16*0.26)+C16 -> 2741.8289 | D13: XXX | E13: XXX | G13: 9.52 | H13: =SUM(H16*0.12)+H16 -> 2046.5316 | I13: =SUM(H16*0.09)+H16 -> 1991.7138 | J13: =SUM(H16*0.09)+H16 -> 1991.7138
B14: 30 | C14: =SUM(C16*0.32)+C16 -> 2872.3922 | D14: XXX | E14: XXX | G14: 12.7 | H14: =SUM(H16*0.12)+H16 -> 2046.5316 | I14: =SUM(H16*0.09)+H16 -> 1991.7138 | J14: =SUM(H16*0.09)+H16 -> 1991.7138
B16: BASE | C16: =SUM(INICIO!K17) -> 2176.0547 | G16: BASE | H16: =SUM(INICIO!Q17) -> 1827.2604 | I16: f24-- 5 | J16: 0.1
B18: 3.17 | C18: 1245 | D18: S/MEL | E18: =SUM(I9*0.1)+I9 -> 2170.7854 | I18: CALIDAD
B19: 4.75 | C19: 1500 | D19: S/MEL | E19: =SUM(J10*0.1)+J10 -> 2170.7854 | I19: ANCHO
B20: 6.35 | C20: 1500 | D20: S/MEL | E20: =SUM(J11*0.1)+J11 -> 2170.7854 | I20: ESPESOR
B23: LISTA DE PRECIOS EN DÓLARES
B24: DD | C24: 1000 | D24: 1220 | E24: 1500 | G24: NEGRA | H24: 1000 | I24: 1245 | J24: 1500
B25: 16 | C25: =SUM(C35*0.07)+C35 -> 1.5543248 | D25: =SUM(C35*0.04)+C35 -> 1.5107456 | E25: =SUM(C35*0.04)+C35 -> 1.5107456 | G25: 1.6 | H25: XXX | I25: XXX | J25: XXX
B26: 18 | C26: =SUM(C35*0.07)+C35 -> 1.5543248 | D26: =SUM(C35*0.04)+C35 -> 1.5107456 | E26: =SUM(C35*0.04)+C35 -> 1.5107456 | G26: 2 | H26: =SUM(H35*0.14)+H35 -> 1.390572 | I26: =SUM(H35*0.11)+H35 -> 1.353978 | J26: XXX
B27: 12,14 y 20 | C27: =SUM(C35*0.08)+C35 -> 1.5688512 | D27: =SUM(C35*0.05)+C35 -> 1.525272 | E27: =SUM(C35*0.05)+C35 -> 1.525272 | G27: 2.5 | H27: =SUM(H35*0.12)+H35 -> 1.366176 | I27: =SUM(H35*0.09)+H35 -> 1.329582 | J27: XXX
B28: 22 | C28: =SUM(C35*0.1)+C35 -> 1.597904 | D28: =SUM(C35*0.07)+C35 -> 1.5543248 | E28: =SUM(C35*0.07)+C35 -> 1.5543248 | G28: 3.17 | H28: =SUM(H35*0.11)+H35 -> 1.353978 | I28: =SUM(H35*0.08)+H35 -> 1.317384 | J28: =SUM(H35*0.08)+H35 -> 1.317384
B29: 0.65 | C29: =SUM(C35*0.12)+C35 -> 1.6269568 | D29: =SUM(C35*0.09)+C35 -> 1.5833776 | E29: XXX | G29: 4,75 Y 4.00 | H29: =SUM(H35*0.11)+H35 -> 1.353978 | I29: =SUM(H35*0.08+H35) -> 1.317384 | J29: =SUM(H35*0.08)+H35 -> 1.317384
B30: 24 | C30: =SUM(C35*0.16)+C35 -> 1.6850624 | D30: =SUM(C35*0.13)+C35 -> 1.6414832 | E30: XXX | G30: 6.35 | H30: =SUM(H35*0.11)+H35 -> 1.353978 | I30: =SUM(H35*0.08)+H35 -> 1.317384 | J30: =SUM(H35*0.08)+H35 -> 1.317384
B31: 26 | C31: =SUM(C35*0.2)+C35 -> 1.743168 | D31: =SUM(C35*0.15)+C35 -> 1.670536 | E31: XXX | G31: 8 | H31: =SUM(H35*0.11)+H35 -> 1.353978 | I31: =SUM(H35*0.08)+H35 -> 1.317384 | J31: =SUM(H35*0.08)+H35 -> 1.317384
B32: 27 | C32: =SUM(C35*0.26)+C35 -> 1.8303264 | D32: XXX | E32: XXX | G32: 9.52 | H32: =SUM(H35*0.12)+H35 -> 1.366176 | I32: =SUM(H35*0.09)+H35 -> 1.329582 | J32: =SUM(H35*0.09)+H35 -> 1.329582
B33: 30 | C33: =SUM(C35*0.32)+C35 -> 1.9174848 | D33: XXX | E33: XXX | G33: 12.7 | H33: =SUM(H35*0.12)+H35 -> 1.366176 | I33: =SUM(H35*0.09)+H35 -> 1.329582 | J33: =SUM(H35*0.09)+H35 -> 1.329582
B35: BASE | C35: =SUM(INICIO!J17) -> 1.45264 | G35: BASE | H35: =SUM(INICIO!P17) -> 1.2198
B37: 3.17 | C37: 1245 | D37: S/MEL | E37: =SUM(I28*0.1)+I28 -> 1.4491224 | I37: CALIDAD
B38: 4.75 | C38: 1500 | D38: S/MEL | E38: =SUM(J29*0.1)+J29 -> 1.4491224 | I38: ANCHO
B39: 6.35 | C39: 1500 | D39: S/MEL | E39: =SUM(J30*0.1)+J30 -> 1.4491224 | I39: ESPESOR
B43: galv | C43: 1000 | D43: 1220
B44: 12 | C44: 0 | D44: 1.4
B45: 16-14 | C45: =SUM(C55*0.07)+C55 -> 0 | D45: 1.422
B46: 18 | C46: 1.473 | D46: 1.43
B47: 20 | C47: =SUM(C55*0.08)+C55 -> 0 | D47: 1.463
B48: 22 | C48: =SUM(C57*0.07)+C57 -> 0 | D48: 1.48
B49: 25 | C49: =SUM(C57*0.08)+C57 -> 0 | D49: 1.492

Sheet 5
B2: CLIENTE: | D2: =PROPER(INICIO!D18) -> Pleg Hurlingham/Tasia/Lujan/San Nicolas/Mesquitq/Santodomingo
B4: LISTA DE PRECIOS EN PESOS
B5: DD | C5: 1000 | D5: 1220 | E5: 1500 | G5: NEGRA | H5: 1000 | I5: 1245 | J5: 1500
B6: 16 | C6: =SUM(C16*0.07)+C16 -> 2224.4331 | D6: =SUM(C16*0.04)+C16 -> 2162.0658 | E6: =SUM(C16*0.04)+C16 -> 2162.0658 | G6: 1.6 | H6: XXX | I6: XXX | J6: XXX
B7: 18 | C7: =SUM(C16*0.07)+C16 -> 2224.4331 | D7: =SUM(C16*0.04)+C16 -> 2162.0658 | E7: =SUM(C16*0.04)+C16 -> 2162.0658 | G7: 2 | H7: =SUM(H16*0.14)+H16 -> 2044.1408 | I7: =SUM(H16*0.11)+H16 -> 1990.3477 | J7: XXX
B8: 12,14 y 20 | C8: =SUM(C16*0.08)+C16 -> 2245.2222 | D8: =SUM(C16*0.05)+C16 -> 2182.8549 | E8: =SUM(C16*0.05)+C16 -> 2182.8549 | G8: 2.5 | H8: =SUM(H16*0.12)+H16 -> 2008.2787 | I8: =SUM(H16*0.09)+H16 -> 1954.4855 | J8: XXX
B9: 22 | C9: =SUM(C16*0.1)+C16 -> 2286.8004 | D9: =SUM(C16*0.07)+C16 -> 2224.4331 | E9: =SUM(C16*0.07)+C16 -> 2224.4331 | G9: 3.17 | H9: =SUM(H16*0.11)+H16 -> 1990.3477 | I9: =SUM(H16*0.08)+H16 -> 1936.5545 | J9: =SUM(H16*0.08)+H16 -> 1936.5545
B10: 0.65 | C10: =SUM(C16*0.12)+C16 -> 2328.3786 | D10: =SUM(C16*0.09)+C16 -> 2266.0113 | E10: XXX | G10: 4,75 Y 4.00 | H10: =SUM(H16*0.11)+H16 -> 1990.3477 | I10: =SUM(H16*0.08+H16) -> 1936.5545 | J10: =SUM(H16*0.07)+H16 -> 1918.6234
B11: 24 | C11: =SUM(C16*0.16)+C16 -> 2411.5349 | D11: =SUM(C16*0.13)+C16 -> 2349.1676 | E11: XXX | G11: 6.35 | H11: =SUM(H16*0.11)+H16 -> 1990.3477 | I11: =SUM(H16*0.08)+H16 -> 1936.5545 | J11: =SUM(H16*0.08)+H16 -> 1936.5545
B12: 26 | C12: =SUM(C16*0.2)+C16 -> 2494.6913 | D12: =SUM(C16*0.15)+C16 -> 2390.7458 | E12: XXX | G12: 8 | H12: =SUM(H16*0.11)+H16 -> 1990.3477 | I12: =SUM(H16*0.08)+H16 -> 1936.5545 | J12: =SUM(H16*0.08)+H16 -> 1936.5545
B13: 27 | C13: =SUM(C16*0.26)+C16 -> 2619.4259 | D13: XXX | E13: XXX | G13: 9.52 | H13: =SUM(H16*0.12)+H16 -> 2008.2787 | I13: =SUM(H16*0.09)+H16 -> 1954.4855 | J13: =SUM(H16*0.1)+H16 -> 1972.4166
B14: 30 | C14: =SUM(C16*0.32)+C16 -> 2744.1604 | D14: XXX | E14: XXX | G14: 12.7 | H14: =SUM(H16*0.12)+H16 -> 2008.2787 | I14: =SUM(H16*0.09)+H16 -> 1954.4855 | J14: =SUM(H16*0.1)+H16 -> 1972.4166
B16: BASE | C16: =SUM(INICIO!K18) -> 2078.9094 | G16: BASE | H16: =SUM(INICIO!Q18) -> 1793.106 | I16: mequi -8 | J16: pasc -11
J17: lujan -10
B18: 3.17 | C18: 1245 | D18: S/MEL | E18: =SUM(I9*0.1)+I9 -> 2130.2099 | I18: CALIDAD | J18: santo -10
B19: 4.75 | C19: 1500 | D19: S/MEL | E19: =SUM(J10*0.1)+J10 -> 2110.4858 | I19: ANCHO
B20: 6.35 | C20: 1500 | D20: S/MEL | E20: =SUM(J11*0.1)+J11 -> 2130.2099 | I20: ESPESOR
B23: LISTA DE PRECIOS EN DÓLARES
B24: DD | C24: 1000 | D24: 1220 | E24: 1500 | G24: NEGRA | H24: 1000 | I24: 1245 | J24: 1500
B25: 16 | C25: =SUM(C35*0.07)+C35 -> 1.4849353 | D25: =SUM(C35*0.04)+C35 -> 1.4433016 | E25: =SUM(C35*0.04)+C35 -> 1.4433016 | G25: 1.6 | H25: XXX | I25: XXX | J25: XXX
B26: 18 | C26: =SUM(C35*0.07)+C35 -> 1.4849353 | D26: =SUM(C35*0.04)+C35 -> 1.4433016 | E26: =SUM(C35*0.04)+C35 -> 1.4433016 | G26: 2 | H26: =SUM(H35*0.14)+H35 -> 1.36458 | I26: =SUM(H35*0.11)+H35 -> 1.32867 | J26: XXX
B27: 12,14 y 20 | C27: =SUM(C35*0.08)+C35 -> 1.4988132 | D27: =SUM(C35*0.05)+C35 -> 1.4571795 | E27: =SUM(C35*0.05)+C35 -> 1.4571795 | G27: 2.5 | H27: =SUM(H35*0.12)+H35 -> 1.34064 | I27: =SUM(H35*0.09)+H35 -> 1.30473 | J27: XXX
B28: 22 | C28: =SUM(C35*0.1)+C35 -> 1.526569 | D28: =SUM(C35*0.07)+C35 -> 1.4849353 | E28: =SUM(C35*0.07)+C35 -> 1.4849353 | G28: 3.17 | H28: =SUM(H35*0.11)+H35 -> 1.32867 | I28: =SUM(H35*0.08)+H35 -> 1.29276 | J28: =SUM(H35*0.08)+H35 -> 1.29276
B29: 0.65 | C29: =SUM(C35*0.12)+C35 -> 1.5543248 | D29: =SUM(C35*0.09)+C35 -> 1.5126911 | E29: XXX | G29: 4,75 Y 4.00 | H29: =SUM(H35*0.1)+H35 -> 1.3167 | I29: =SUM(H35*0.07+H35) -> 1.28079 | J29: =SUM(H35*0.07)+H35 -> 1.28079
B30: 24 | C30: =SUM(C35*0.16)+C35 -> 1.6098364 | D30: =SUM(C35*0.13)+C35 -> 1.5682027 | E30: XXX | G30: 6.35 | H30: =SUM(H35*0.11)+H35 -> 1.32867 | I30: =SUM(H35*0.08)+H35 -> 1.29276 | J30: =SUM(H35*0.08)+H35 -> 1.29276
B31: 26 | C31: =SUM(C35*0.2)+C35 -> 1.665348 | D31: =SUM(C35*0.15)+C35 -> 1.5959585 | E31: XXX | G31: 8 | H31: =SUM(H35*0.11)+H35 -> 1.32867 | I31: =SUM(H35*0.08)+H35 -> 1.29276 | J31: =SUM(H35*0.08)+H35 -> 1.29276
B32: 27 | C32: =SUM(C35*0.26)+C35 -> 1.7486154 | D32: XXX | E32: XXX | G32: 9.52 | H32: =SUM(H35*0.12)+H35 -> 1.34064 | I32: =SUM(H35*0.09)+H35 -> 1.30473 | J32: =SUM(H35*0.1)+H35 -> 1.3167
B33: 30 | C33: =SUM(C35*0.32)+C35 -> 1.8318828 | D33: XXX | E33: XXX | G33: 12.7 | H33: =SUM(H35*0.12)+H35 -> 1.34064 | I33: =SUM(H35*0.09)+H35 -> 1.30473 | J33: =SUM(H35*0.1)+H35 -> 1.3167
B35: BASE | C35: =SUM(INICIO!J18) -> 1.38779 | G35: BASE | H35: =SUM(INICIO!P18) -> 1.197
B37: 3.17 | C37: 1245 | D37: S/MEL | E37: =SUM(I28*0.1)+I28 -> 1.422036 | I37: CALIDAD
B38: 4.75 | C38: 1500 | D38: S/MEL | E38: =SUM(J29*0.1)+J29 -> 1.408869 | I38: ANCHO
B39: 6.35 | C39: 1500 | D39: S/MEL | E39: =SUM(J30*0.1)+J30 -> 1.422036 | I39: ESPESOR

Sheet 6
B2: CLIENTE: | D2: =PROPER(INICIO!D19) -> Oxpane Laser/Milsa/Viane
B4: LISTA DE PRECIOS EN PESOS
B5: DD | C5: 1000 | D5: 1220 | E5: 1500 | G5: NEGRA | H5: 1000 | I5: 1245 | J5: 1500
B6: 16 | C6: =SUM(C16*0.07)+C16 -> 2203.644 | D6: =SUM(C16*0.04)+C16 -> 2141.8596 | E6: =SUM(C16*0.04)+C16 -> 2141.8596 | G6: 1.6 | H6: XXX | I6: XXX | J6: XXX
B7: 18 | C7: =SUM(C16*0.07)+C16 -> 2203.644 | D7: =SUM(C16*0.04)+C16 -> 2141.8596 | E7: =SUM(C16*0.04)+C16 -> 2141.8596 | G7: 2 | H7: =SUM(H16*0.14)+H16 -> 1966.2688 | I7: =SUM(H16*0.11)+H16 -> 1914.5249 | J7: XXX
B8: 12,14 y 20 | C8: =SUM(C16*0.08)+C16 -> 2224.2388 | D8: =SUM(C16*0.05)+C16 -> 2162.4544 | E8: =SUM(C16*0.05)+C16 -> 2162.4544 | G8: 2.5 | H8: =SUM(H16*0.12)+H16 -> 1931.7729 | I8: =SUM(H16*0.09)+H16 -> 1880.0289 | J8: XXX
B9: 22 | C9: =SUM(C16*0.1)+C16 -> 2265.4284 | D9: =SUM(C16*0.07)+C16 -> 2203.644 | E9: =SUM(C16*0.07)+C16 -> 2203.644 | G9: 3.17 | H9: =SUM(H16*0.11)+H16 -> 1914.5249 | I9: =SUM(H16*0.08)+H16 -> 1862.781 | J9: =SUM(H16*0.08)+H16 -> 1862.781
B10: 0.65 | C10: =SUM(C16*0.12)+C16 -> 2306.618 | D10: =SUM(C16*0.09)+C16 -> 2244.8336 | E10: XXX | G10: 4,75 Y 4.00 | H10: =SUM(H16*0.11)+H16 -> 1914.5249 | I10: =SUM(H16*0.08+H16) -> 1862.781 | J10: =SUM(H16*0.08)+H16 -> 1862.781
B11: 24 | C11: =SUM(C16*0.16)+C16 -> 2388.9972 | D11: =SUM(C16*0.13)+C16 -> 2327.2128 | E11: XXX | G11: 6.35 | H11: =SUM(H16*0.11)+H16 -> 1914.5249 | I11: =SUM(H16*0.08)+H16 -> 1862.781 | J11: =SUM(H16*0.08)+H16 -> 1862.781
B12: 26 | C12: =SUM(C16*0.2)+C16 -> 2471.3764 | D12: =SUM(C16*0.15)+C16 -> 2368.4024 | E12: XXX | G12: 8 | H12: =SUM(H16*0.11)+H16 -> 1914.5249 | I12: =SUM(H16*0.08)+H16 -> 1862.781 | J12: =SUM(H16*0.08)+H16 -> 1862.781
B13: 27 | C13: =SUM(C16*0.26)+C16 -> 2594.9453 | D13: XXX | E13: XXX | G13: 9.52 | H13: =SUM(H16*0.12)+H16 -> 1931.7729 | I13: =SUM(H16*0.09)+H16 -> 1880.0289 | J13: =SUM(H16*0.09)+H16 -> 1880.0289
B14: 30 | C14: =SUM(C16*0.32)+C16 -> 2718.5141 | D14: XXX | E14: XXX | G14: 12.7 | H14: =SUM(H16*0.12)+H16 -> 1931.7729 | I14: =SUM(H16*0.09)+H16 -> 1880.0289 | J14: =SUM(H16*0.09)+H16 -> 1880.0289
B16: BASE | C16: =SUM(INICIO!K19) -> 2059.4804 | G16: BASE | H16: =SUM(INICIO!Q19) -> 1724.7972 | J16: decapada 8,5
J17: oxp-11% | K17: angosta 915
B18: 3.17 | C18: 1245 | D18: S/MEL | E18: =SUM(I9*0.1)+I9 -> 2049.0591 | I18: CALIDAD | J18: milsa -8
B19: 4.75 | C19: 1500 | D19: S/MEL | E19: =SUM(J10*0.1)+J10 -> 2049.0591 | I19: ANCHO | J19: viane
B20: 6.35 | C20: 1500 | D20: S/MEL | E20: =SUM(J11*0.1)+J11 -> 2049.0591 | I20: ESPESOR
B23: LISTA DE PRECIOS EN DÓLARES
B24: DD | C24: 1000 | D24: 1220 | E24: 1500 | G24: NEGRA | H24: 1000 | I24: 1245 | J24: 1500
B25: 16 | C25: =SUM(C35*0.07)+C35 -> 1.4710574 | D25: =SUM(C35*0.04)+C35 -> 1.4298128 | E25: =SUM(C35*0.04)+C35 -> 1.4298128 | G25: 1.6 | H25: XXX | I25: XXX | J25: XXX
B26: 18 | C26: =SUM(C35*0.07)+C35 -> 1.4710574 | D26: =SUM(C35*0.04)+C35 -> 1.4298128 | E26: =SUM(C35*0.04)+C35 -> 1.4298128 | G26: 2 | H26: =SUM(H35*0.14)+H35 -> 1.312596 | I26: =SUM(H35*0.11)+H35 -> 1.278054 | J26: XXX
B27: 12,14 y 20 | C27: =SUM(C35*0.08)+C35 -> 1.4848056 | D27: =SUM(C35*0.05)+C35 -> 1.443561 | E27: =SUM(C35*0.05)+C35 -> 1.443561 | G27: 2.5 | H27: =SUM(H35*0.12)+H35 -> 1.289568 | I27: =SUM(H35*0.09)+H35 -> 1.255026 | J27: XXX
B28: 22 | C28: =SUM(C35*0.1)+C35 -> 1.512302 | D28: =SUM(C35*0.07)+C35 -> 1.4710574 | E28: =SUM(C35*0.07)+C35 -> 1.4710574 | G28: 3.17 | H28: =SUM(H35*0.11)+H35 -> 1.278054 | I28: =SUM(H35*0.08)+H35 -> 1.243512 | J28: =SUM(H35*0.08)+H35 -> 1.243512
B29: 0.65 | C29: =SUM(C35*0.12)+C35 -> 1.5397984 | D29: =SUM(C35*0.09)+C35 -> 1.4985538 | E29: XXX | G29: 4,75 Y 4.00 | H29: =SUM(H35*0.1)+H35 -> 1.26654 | I29: =SUM(H35*0.07+H35) -> 1.231998 | J29: =SUM(H35*0.07)+H35 -> 1.231998
B30: 24 | C30: =SUM(C35*0.16)+C35 -> 1.5947912 | D30: =SUM(C35*0.13)+C35 -> 1.5535466 | E30: XXX | G30: 6.35 | H30: =SUM(H35*0.11)+H35 -> 1.278054 | I30: =SUM(H35*0.08)+H35 -> 1.243512 | J30: =SUM(H35*0.08)+H35 -> 1.243512
B31: 26 | C31: =SUM(C35*0.2)+C35 -> 1.649784 | D31: =SUM(C35*0.15)+C35 -> 1.581043 | E31: XXX | G31: 8 | H31: =SUM(H35*0.11)+H35 -> 1.278054 | I31: =SUM(H35*0.08)+H35 -> 1.243512 | J31: =SUM(H35*0.08)+H35 -> 1.243512
B32: 27 | C32: =SUM(C35*0.26)+C35 -> 1.7322732 | D32: XXX | E32: XXX | G32: 9.52 | H32: =SUM(H35*0.12)+H35 -> 1.289568 | I32: =SUM(H35*0.09)+H35 -> 1.255026 | J32: =SUM(H35*0.09)+H35 -> 1.255026
B33: 30 | C33: =SUM(C35*0.32)+C35 -> 1.8147624 | D33: XXX | E33: XXX | G33: 12.7 | H33: =SUM(H35*0.12)+H35 -> 1.289568 | I33: =SUM(H35*0.09)+H35 -> 1.255026 | J33: =SUM(H35*0.09)+H35 -> 1.255026
B35: BASE | C35: =SUM(INICIO!J19) -> 1.37482 | G35: BASE | H35: =SUM(INICIO!P19) -> 1.1514
B37: 3.17 | C37: 1245 | D37: S/MEL | E37: =SUM(I28*0.1)+I28 -> 1.3678632 | I37: CALIDAD
B38: 4.75 | C38: 1500 | D38: S/MEL | E38: =SUM(J29*0.1)+J29 -> 1.3551978 | I38: ANCHO
B39: 6.35 | C39: 1500 | D39: S/MEL | E39: =SUM(J30*0.1)+J30 -> 1.3678632 | I39: ESPESOR

Sheet 8
B2: CLIENTE: | D2: =PROPER(INICIO!D21) -> Cormot/Geluma/Merigui/Lumak
B4: LISTA DE PRECIOS EN PESOS
B5: DD | C5: 1000 | D5: 1220 | E5: 1500 | G5: NEGRA | H5: 1000 | I5: 1245 | J5: 1500
B6: 16 | C6: =SUM(C16*0.07)+C16 -> 2328.3786 | D6: =SUM(C16*0.04)+C16 -> 2263.0969 | E6: =SUM(C16*0.04)+C16 -> 2263.0969 | G6: 1.6 | H6: XXX | I6: XXX | J6: XXX
B7: 18 | C7: =SUM(C16*0.07)+C16 -> 2328.3786 | D7: =SUM(C16*0.04)+C16 -> 2263.0969 | E7: =SUM(C16*0.04)+C16 -> 2263.0969 | G7: 2 | H7: =SUM(H16*0.14)+H16 -> 2122.0129 | I7: =SUM(H16*0.11)+H16 -> 2066.1704 | J7: XXX
B8: 12,14 y 20 | C8: =SUM(C16*0.08)+C16 -> 2350.1391 | D8: =SUM(C16*0.05)+C16 -> 2284.8575 | E8: =SUM(C16*0.05)+C16 -> 2284.8575 | G8: 2.5 | H8: =SUM(H16*0.12)+H16 -> 2084.7846 | I8: =SUM(H16*0.09)+H16 -> 2028.9421 | J8: XXX
B9: 22 | C9: =SUM(C16*0.1)+C16 -> 2393.6602 | D9: =SUM(C16*0.07)+C16 -> 2328.3786 | E9: =SUM(C16*0.07)+C16 -> 2328.3786 | G9: 3.17 | H9: =SUM(H16*0.11)+H16 -> 2066.1704 | I9: =SUM(H16*0.08)+H16 -> 2010.328 | J9: =SUM(H16*0.08)+H16 -> 2010.328
B10: 0.65 | C10: =SUM(C16*0.12)+C16 -> 2437.1813 | D10: =SUM(C16*0.09)+C16 -> 2371.8996 | E10: XXX | G10: 4,75 Y 4.00 | H10: =SUM(H16*0.1)+H16 -> 2047.5563 | I10: =SUM(H16*0.07+H16) -> 1991.7138 | J10: =SUM(H16*0.07)+H16 -> 1991.7138
B11: 24 | C11: =SUM(C16*0.16)+C16 -> 2524.2235 | D11: =SUM(C16*0.13)+C16 -> 2458.9418 | E11: XXX | G11: 6.35 | H11: =SUM(H16*0.11)+H16 -> 2066.1704 | I11: =SUM(H16*0.08)+H16 -> 2010.328 | J11: =SUM(H16*0.08)+H16 -> 2010.328
B12: 26 | C12: =SUM(C16*0.2)+C16 -> 2611.2657 | D12: =SUM(C16*0.15)+C16 -> 2502.4629 | E12: XXX | G12: 8 | H12: =SUM(H16*0.11)+H16 -> 2066.1704 | I12: =SUM(H16*0.08)+H16 -> 2010.328 | J12: =SUM(H16*0.08)+H16 -> 2010.328
B13: 27 | C13: =SUM(C16*0.26)+C16 -> 2741.8289 | D13: XXX | E13: XXX | G13: 9.52 | H13: =SUM(H16*0.12)+H16 -> 2084.7846 | I13: =SUM(H16*0.09)+H16 -> 2028.9421 | J13: =SUM(H16*0.1)+H16 -> 2047.5563
B14: 30 | C14: =SUM(C16*0.32)+C16 -> 2872.3922 | D14: XXX | E14: XXX | G14: 12.7 | H14: =SUM(H16*0.12)+H16 -> 2084.7846 | I14: =SUM(H16*0.09)+H16 -> 2028.9421 | J14: =SUM(H16*0.1)+H16 -> 2047.5563
B16: BASE | C16: =SUM(INICIO!K21) -> 2176.0547 | G16: BASE | H16: =SUM(INICIO!Q21) -> 1861.4148 | J16: cormot -5
B18: 3.17 | C18: 1245 | D18: S/MEL | E18: =SUM(I9*0.1)+I9 -> 2211.3608 | I18: CALIDAD
B19: 4.75 | C19: 1500 | D19: S/MEL | E19: =SUM(J10*0.1)+J10 -> 2190.8852 | I19: ANCHO
B20: 6.35 | C20: 1500 | D20: S/MEL | E20: =SUM(J11*0.1)+J11 -> 2211.3608 | I20: ESPESOR
B23: LISTA DE PRECIOS EN DÓLARES
B24: DD | C24: 1000 | D24: 1220 | E24: 1500 | G24: NEGRA | H24: 1000 | I24: 1245 | J24: 1500
B25: 16 | C25: =SUM(C35*0.07)+C35 -> 1.5543248 | D25: =SUM(C35*0.04)+C35 -> 1.5107456 | E25: =SUM(C35*0.04)+C35 -> 1.5107456 | G25: 1.6 | H25: XXX | I25: XXX | J25: XXX
B26: 18 | C26: =SUM(C35*0.07)+C35 -> 1.5543248 | D26: =SUM(C35*0.04)+C35 -> 1.5107456 | E26: =SUM(C35*0.04)+C35 -> 1.5107456 | G26: 2 | H26: =SUM(H35*0.14)+H35 -> 1.416564 | I26: =SUM(H35*0.11)+H35 -> 1.379286 | J26: XXX
B27: 12,14 y 20 | C27: =SUM(C35*0.08)+C35 -> 1.5688512 | D27: =SUM(C35*0.05)+C35 -> 1.525272 | E27: =SUM(C35*0.05)+C35 -> 1.525272 | G27: 2.5 | H27: =SUM(H35*0.12)+H35 -> 1.391712 | I27: =SUM(H35*0.09)+H35 -> 1.354434 | J27: XXX
B28: 22 | C28: =SUM(C35*0.1)+C35 -> 1.597904 | D28: =SUM(C35*0.07)+C35 -> 1.5543248 | E28: =SUM(C35*0.07)+C35 -> 1.5543248 | G28: 3.17 | H28: =SUM(H35*0.11)+H35 -> 1.379286 | I28: =SUM(H35*0.08)+H35 -> 1.342008 | J28: =SUM(H35*0.08)+H35 -> 1.342008
B29: 0.65 | C29: =SUM(C35*0.12)+C35 -> 1.6269568 | D29: =SUM(C35*0.09)+C35 -> 1.5833776 | E29: XXX | G29: 4,75 Y 4.00 | H29: =SUM(H35*0.1)+H35 -> 1.36686 | I29: =SUM(H35*0.07+H35) -> 1.329582 | J29: =SUM(H35*0.07)+H35 -> 1.329582
B30: 24 | C30: =SUM(C35*0.16)+C35 -> 1.6850624 | D30: =SUM(C35*0.13)+C35 -> 1.6414832 | E30: XXX | G30: 6.35 | H30: =SUM(H35*0.11)+H35 -> 1.379286 | I30: =SUM(H35*0.08)+H35 -> 1.342008 | J30: =SUM(H35*0.08)+H35 -> 1.342008
B31: 26 | C31: =SUM(C35*0.2)+C35 -> 1.743168 | D31: =SUM(C35*0.15)+C35 -> 1.670536 | E31: XXX | G31: 8 | H31: =SUM(H35*0.11)+H35 -> 1.379286 | I31: =SUM(H35*0.08)+H35 -> 1.342008 | J31: =SUM(H35*0.08)+H35 -> 1.342008
B32: 27 | C32: =SUM(C35*0.26)+C35 -> 1.8303264 | D32: XXX | E32: XXX | G32: 9.52 | H32: =SUM(H35*0.12)+H35 -> 1.391712 | I32: =SUM(H35*0.09)+H35 -> 1.354434 | J32: =SUM(H35*0.1)+H35 -> 1.36686
B33: 30 | C33: =SUM(C35*0.32)+C35 -> 1.9174848 | D33: XXX | E33: XXX | G33: 12.7 | H33: =SUM(H35*0.12)+H35 -> 1.391712 | I33: =SUM(H35*0.09)+H35 -> 1.354434 | J33: =SUM(H35*0.1)+H35 -> 1.36686
B35: BASE | C35: =SUM(INICIO!J21) -> 1.45264 | G35: BASE | H35: =SUM(INICIO!P21) -> 1.2426 | I35: sae 1045 | J35: 1.4
B37: 3.17 | C37: 1245 | D37: S/MEL | E37: =SUM(I28*0.1)+I28 -> 1.4762088 | I37: CALIDAD
B38: 4.75 | C38: 1500 | D38: S/MEL | E38: =SUM(J29*0.1)+J29 -> 1.4625402 | I38: ANCHO
B39: 6.35 | C39: 1500 | D39: S/MEL | E39: =SUM(J30*0.1)+J30 -> 1.4762088 | I39: ESPESOR

Sheet 7
B2: CLIENTE: | D2: =PROPER(INICIO!D20) -> Gor Gras/Rase/Calcor/Fabrica De Luz/Forjan/Lagos
B4: LISTA DE PRECIOS EN PESOS
B5: DD | C5: 1000 | D5: 1220 | E5: 1500 | G5: NEGRA | H5: 1000 | I5: 1245 | J5: 1500
B6: 16 | C6: =SUM(C16*0.07)+C16 -> 2349.1676 | D6: =SUM(C16*0.04)+C16 -> 2283.3031 | E6: =SUM(C16*0.04)+C16 -> 2283.3031 | G6: 1.6 | H6: XXX | I6: XXX | J6: XXX
B7: 18 | C7: =SUM(C16*0.07)+C16 -> 2349.1676 | D7: =SUM(C16*0.04)+C16 -> 2283.3031 | E7: =SUM(C16*0.04)+C16 -> 2283.3031 | G7: 2 | H7: =SUM(H16*0.14)+H16 -> 2122.0129 | I7: =SUM(H16*0.11)+H16 -> 2066.1704 | J7: XXX
B8: 12,14 y 20 | C8: =SUM(C16*0.08)+C16 -> 2371.1225 | D8: =SUM(C16*0.05)+C16 -> 2305.258 | E8: =SUM(C16*0.05)+C16 -> 2305.258 | G8: 2.5 | H8: =SUM(H16*0.12)+H16 -> 2084.7846 | I8: =SUM(H16*0.09)+H16 -> 2028.9421 | J8: XXX
B9: 22 | C9: =SUM(C16*0.1)+C16 -> 2415.0322 | D9: =SUM(C16*0.07)+C16 -> 2349.1676 | E9: =SUM(C16*0.07)+C16 -> 2349.1676 | G9: 3.17 | H9: =SUM(H16*0.11)+H16 -> 2066.1704 | I9: =SUM(H16*0.08)+H16 -> 2010.328 | J9: =SUM(H16*0.08)+H16 -> 2010.328
B10: 0.65 | C10: =SUM(C16*0.12)+C16 -> 2458.9418 | D10: =SUM(C16*0.09)+C16 -> 2393.0773 | E10: XXX | G10: 4,75 Y 4.00 | H10: =SUM(H16*0.1)+H16 -> 2047.5563 | I10: =SUM(H16*0.07+H16) -> 1991.7138 | J10: =SUM(H16*0.07)+H16 -> 1991.7138
B11: 24 | C11: =SUM(C16*0.16)+C16 -> 2546.7612 | D11: =SUM(C16*0.13)+C16 -> 2480.8967 | E11: XXX | G11: 6.35 | H11: =SUM(H16*0.11)+H16 -> 2066.1704 | I11: =SUM(H16*0.08)+H16 -> 2010.328 | J11: =SUM(H16*0.08)+H16 -> 2010.328
B12: 26 | C12: =SUM(C16*0.2)+C16 -> 2634.5805 | D12: =SUM(C16*0.15)+C16 -> 2524.8063 | E12: XXX | G12: 8 | H12: =SUM(H16*0.11)+H16 -> 2066.1704 | I12: =SUM(H16*0.08)+H16 -> 2010.328 | J12: =SUM(H16*0.08)+H16 -> 2010.328
B13: 27 | C13: =SUM(C16*0.26)+C16 -> 2766.3096 | D13: XXX | E13: XXX | G13: 9.52 | H13: =SUM(H16*0.12)+H16 -> 2084.7846 | I13: =SUM(H16*0.09)+H16 -> 2028.9421 | J13: =SUM(H16*0.09)+H16 -> 2028.9421
B14: 30 | C14: =SUM(C16*0.32)+C16 -> 2898.0386 | D14: XXX | E14: XXX | G14: 12.7 | H14: =SUM(H16*0.12)+H16 -> 2084.7846 | I14: =SUM(H16*0.09)+H16 -> 2028.9421 | J14: =SUM(H16*0.09)+H16 -> 2028.9421
B16: BASE | C16: =SUM(INICIO!K20) -> 2195.4838 | G16: BASE | H16: =SUM(INICIO!Q20) -> 1861.4148 | J16: -0.1
B18: 3.17 | C18: 1245 | D18: S/MEL | E18: =SUM(I9*0.1)+I9 -> 2211.3608 | I18: CALIDAD
B19: 4.75 | C19: 1500 | D19: S/MEL | E19: =SUM(J10*0.1)+J10 -> 2190.8852 | I19: ANCHO
B20: 6.35 | C20: 1500 | D20: S/MEL | E20: =SUM(J11*0.1)+J11 -> 2211.3608 | I20: ESPESOR
B24: LISTA DE PRECIOS EN DÓLARES
B25: DD | C25: 1000 | D25: 1220 | E25: 1500 | G25: NEGRA | H25: 1000 | I25: 1245 | J25: 1500
B26: 16 | C26: =SUM(C36*0.07)+C36 -> 1.5682027 | D26: =SUM(C36*0.04)+C36 -> 1.5242344 | E26: =SUM(C36*0.04)+C36 -> 1.5242344 | G26: 1.6 | H26: XXX | I26: XXX | J26: XXX
B27: 18 | C27: =SUM(C36*0.07)+C36 -> 1.5682027 | D27: =SUM(C36*0.04)+C36 -> 1.5242344 | E27: =SUM(C36*0.04)+C36 -> 1.5242344 | G27: 2 | H27: =SUM(H36*0.14)+H36 -> 1.416564 | I27: =SUM(H36*0.11)+H36 -> 1.379286 | J27: XXX
B28: 12,14 y 20 | C28: =SUM(C36*0.08)+C36 -> 1.5828588 | D28: =SUM(C36*0.05)+C36 -> 1.5388905 | E28: =SUM(C36*0.05)+C36 -> 1.5388905 | G28: 2.5 | H28: =SUM(H36*0.12)+H36 -> 1.391712 | I28: =SUM(H36*0.09)+H36 -> 1.354434 | J28: XXX
B29: 22 | C29: =SUM(C36*0.1)+C36 -> 1.612171 | D29: =SUM(C36*0.07)+C36 -> 1.5682027 | E29: =SUM(C36*0.07)+C36 -> 1.5682027 | G29: 3.17 | H29: =SUM(H36*0.11)+H36 -> 1.379286 | I29: =SUM(H36*0.08)+H36 -> 1.342008 | J29: =SUM(H36*0.08)+H36 -> 1.342008
B30: 0.65 | C30: =SUM(C36*0.12)+C36 -> 1.6414832 | D30: =SUM(C36*0.09)+C36 -> 1.5975149 | E30: XXX | G30: 4,75 Y 4.00 | H30: =SUM(H36*0.1)+H36 -> 1.36686 | I30: =SUM(H36*0.07+H36) -> 1.329582 | J30: =SUM(H36*0.07)+H36 -> 1.329582
B31: 24 | C31: =SUM(C36*0.16)+C36 -> 1.7001076 | D31: =SUM(C36*0.13)+C36 -> 1.6561393 | E31: XXX | G31: 6.35 | H31: =SUM(H36*0.11)+H36 -> 1.379286 | I31: =SUM(H36*0.08)+H36 -> 1.342008 | J31: =SUM(H36*0.08)+H36 -> 1.342008
B32: 26 | C32: =SUM(C36*0.2)+C36 -> 1.758732 | D32: =SUM(C36*0.15)+C36 -> 1.6854515 | E32: XXX | G32: 8 | H32: =SUM(H36*0.11)+H36 -> 1.379286 | I32: =SUM(H36*0.08)+H36 -> 1.342008 | J32: =SUM(H36*0.08)+H36 -> 1.342008
B33: 27 | C33: =SUM(C36*0.26)+C36 -> 1.8466686 | D33: XXX | E33: XXX | G33: 9.52 | H33: =SUM(H36*0.12)+H36 -> 1.391712 | I33: =SUM(H36*0.09)+H36 -> 1.354434 | J33: =SUM(H36*0.09)+H36 -> 1.354434
B34: 30 | C34: =SUM(C36*0.32)+C36 -> 1.9346052 | D34: XXX | E34: XXX | G34: 12.7 | H34: =SUM(H36*0.12)+H36 -> 1.391712 | I34: =SUM(H36*0.09)+H36 -> 1.354434 | J34: =SUM(H36*0.09)+H36 -> 1.354434
B36: BASE | C36: =SUM(INICIO!J20) -> 1.46561 | G36: BASE | H36: =SUM(INICIO!P20) -> 1.2426
B38: 3.17 | C38: 1245 | D38: S/MEL | E38: =SUM(I29*0.1)+I29 -> 1.4762088 | I38: CALIDAD
B39: 4.75 | C39: 1500 | D39: S/MEL | E39: =SUM(J30*0.1)+J30 -> 1.4625402 | I39: ANCHO
B40: 6.35 | C40: 1500 | D40: S/MEL | E40: =SUM(J31*0.1)+J31 -> 1.4762088 | I40: ESPESOR

Sheet 9
B2: CLIENTE: | D2: =PROPER(INICIO!D22) -> Int Pomp/Gustavo Carrocero
B4: LISTA DE PRECIOS EN PESOS
B5: DD | C5: 1000 | D5: 1220 | E5: 1500 | G5: NEGRA | H5: 1000 | I5: 1245 | J5: 1500
B6: 16 | C6: =SUM(C16*0.07)+C16 -> 2328.3786 | D6: =SUM(C16*0.04)+C16 -> 2263.0969 | E6: =SUM(C16*0.04)+C16 -> 2263.0969 | G6: 1.6 | H6: XXX | I6: XXX | J6: XXX
B7: 18 | C7: =SUM(C16*0.07)+C16 -> 2328.3786 | D7: =SUM(C16*0.04)+C16 -> 2263.0969 | E7: =SUM(C16*0.04)+C16 -> 2263.0969 | G7: 2 | H7: =SUM(H16*0.14)+H16 -> 2102.5449 | I7: =SUM(H16*0.11)+H16 -> 2047.2147 | J7: XXX
B8: 12,14 y 20 | C8: =SUM(C16*0.08)+C16 -> 2350.1391 | D8: =SUM(C16*0.05)+C16 -> 2284.8575 | E8: =SUM(C16*0.05)+C16 -> 2284.8575 | G8: 2.5 | H8: =SUM(H16*0.12)+H16 -> 2065.6581 | I8: =SUM(H16*0.09)+H16 -> 2010.328 | J8: XXX
B9: 22 | C9: =SUM(C16*0.1)+C16 -> 2393.6602 | D9: =SUM(C16*0.07)+C16 -> 2328.3786 | E9: =SUM(C16*0.07)+C16 -> 2328.3786 | G9: 3.17 | H9: =SUM(H16*0.11)+H16 -> 2047.2147 | I9: =SUM(H16*0.08)+H16 -> 1991.8846 | J9: =SUM(H16*0.08)+H16 -> 1991.8846
B10: 0.65 | C10: =SUM(C16*0.12)+C16 -> 2437.1813 | D10: =SUM(C16*0.09)+C16 -> 2371.8996 | E10: XXX | G10: 4,75 Y 4.00 | H10: =SUM(H16*0.1)+H16 -> 2028.7714 | I10: =SUM(H16*0.07+H16) -> 1973.4412 | J10: =SUM(H16*0.07)+H16 -> 1973.4412
B11: 24 | C11: =SUM(C16*0.16)+C16 -> 2524.2235 | D11: =SUM(C16*0.13)+C16 -> 2458.9418 | E11: XXX | G11: 6.35 | H11: =SUM(H16*0.11)+H16 -> 2047.2147 | I11: =SUM(H16*0.08)+H16 -> 1991.8846 | J11: =SUM(H16*0.08)+H16 -> 1991.8846
B12: 26 | C12: =SUM(C16*0.2)+C16 -> 2611.2657 | D12: =SUM(C16*0.15)+C16 -> 2502.4629 | E12: XXX | G12: 8 | H12: =SUM(H16*0.11)+H16 -> 2047.2147 | I12: =SUM(H16*0.08)+H16 -> 1991.8846 | J12: =SUM(H16*0.08)+H16 -> 1991.8846
B13: 27 | C13: =SUM(C16*0.26)+C16 -> 2741.8289 | D13: XXX | E13: XXX | G13: 9.52 | H13: =SUM(H16*0.12)+H16 -> 2065.6581 | I13: =SUM(H16*0.09)+H16 -> 2010.328 | J13: =SUM(H16*0.1)+H16 -> 2028.7714
B14: 30 | C14: =SUM(C16*0.32)+C16 -> 2872.3922 | D14: XXX | E14: XXX | G14: 12.7 | H14: =SUM(H16*0.12)+H16 -> 2065.6581 | I14: =SUM(H16*0.09)+H16 -> 2010.328 | J14: =SUM(H16*0.1)+H16 -> 2028.7714
B16: BASE | C16: =SUM(INICIO!K22) -> 2176.0547 | G16: BASE | H16: =SUM(INICIO!Q22) -> 1844.3376 | I16: DEC
B18: 3.17 | C18: 1245 | D18: S/MEL | E18: =SUM(I9*0.1)+I9 -> 2191.0731 | I18: CALIDAD
B19: 4.75 | C19: 1500 | D19: S/MEL | E19: =SUM(J10*0.1)+J10 -> 2170.7854 | I19: ANCHO
B20: 6.35 | C20: 1500 | D20: S/MEL | E20: =SUM(J11*0.1)+J11 -> 2191.0731 | I20: ESPESOR
B22: LISTA DE PRECIOS EN DÓLARES
B23: DD | C23: 1000 | D23: 1220 | E23: 1500 | G23: NEGRA | H23: 1000 | I23: 1245 | J23: 1500
B24: 16 | C24: =SUM(C34*0.07)+C34 -> 1.5543248 | D24: =SUM(C34*0.04)+C34 -> 1.5107456 | E24: =SUM(C34*0.04)+C34 -> 1.5107456 | G24: 1.6 | H24: XXX | I24: XXX | J24: XXX
B25: 18 | C25: =SUM(C34*0.07)+C34 -> 1.5543248 | D25: =SUM(C34*0.04)+C34 -> 1.5107456 | E25: =SUM(C34*0.04)+C34 -> 1.5107456 | G25: 2 | H25: =SUM(H34*0.14)+H34 -> 1.403568 | I25: =SUM(H34*0.11)+H34 -> 1.366632 | J25: XXX
B26: 12,14 y 20 | C26: =SUM(C34*0.08)+C34 -> 1.5688512 | D26: =SUM(C34*0.05)+C34 -> 1.525272 | E26: =SUM(C34*0.05)+C34 -> 1.525272 | G26: 2.5 | H26: =SUM(H34*0.12)+H34 -> 1.378944 | I26: =SUM(H34*0.09)+H34 -> 1.342008 | J26: XXX
B27: 22 | C27: =SUM(C34*0.1)+C34 -> 1.597904 | D27: =SUM(C34*0.07)+C34 -> 1.5543248 | E27: =SUM(C34*0.07)+C34 -> 1.5543248 | G27: 3.17 | H27: =SUM(H34*0.11)+H34 -> 1.366632 | I27: =SUM(H34*0.08)+H34 -> 1.329696 | J27: =SUM(H34*0.08)+H34 -> 1.329696
B28: 0.65 | C28: =SUM(C34*0.12)+C34 -> 1.6269568 | D28: =SUM(C34*0.09)+C34 -> 1.5833776 | E28: XXX | G28: 4,75 Y 4.00 | H28: =SUM(H34*0.1)+H34 -> 1.35432 | I28: =SUM(H34*0.07+H34) -> 1.317384 | J28: =SUM(H34*0.07)+H34 -> 1.317384
B29: 24 | C29: =SUM(C34*0.16)+C34 -> 1.6850624 | D29: =SUM(C34*0.13)+C34 -> 1.6414832 | E29: XXX | G29: 6.35 | H29: =SUM(H34*0.11)+H34 -> 1.366632 | I29: =SUM(H34*0.08)+H34 -> 1.329696 | J29: =SUM(H34*0.08)+H34 -> 1.329696
B30: 26 | C30: =SUM(C34*0.2)+C34 -> 1.743168 | D30: =SUM(C34*0.15)+C34 -> 1.670536 | E30: XXX | G30: 8 | H30: =SUM(H34*0.11)+H34 -> 1.366632 | I30: =SUM(H34*0.08)+H34 -> 1.329696 | J30: =SUM(H34*0.08)+H34 -> 1.329696
B31: 27 | C31: =SUM(C34*0.26)+C34 -> 1.8303264 | D31: XXX | E31: XXX | G31: 9.52 | H31: =SUM(H34*0.12)+H34 -> 1.378944 | I31: =SUM(H34*0.09)+H34 -> 1.342008 | J31: =SUM(H34*0.1)+H34 -> 1.35432
B32: 30 | C32: =SUM(C34*0.32)+C34 -> 1.9174848 | D32: XXX | E32: XXX | G32: 12.7 | H32: =SUM(H34*0.12)+H34 -> 1.378944 | I32: =SUM(H34*0.09)+H34 -> 1.342008 | J32: =SUM(H34*0.1)+H34 -> 1.35432
B34: BASE | C34: =SUM(INICIO!J22) -> 1.45264 | G34: BASE | H34: =SUM(INICIO!P22) -> 1.2312
B36: 3.17 | C36: 1245 | D36: S/MEL | E36: =SUM(I27*0.1)+I27 -> 1.4626656 | I36: CALIDAD
B37: 4.75 | C37: 1500 | D37: S/MEL | E37: =SUM(J28*0.1)+J28 -> 1.4491224 | I37: ANCHO
B38: 6.35 | C38: 1500 | D38: S/MEL | E38: =SUM(J29*0.1)+J29 -> 1.4626656 | I38: ESPESOR

Sheet 10
B2: CLIENTE: | D2: =PROPER(INICIO!D23) -> Di Lorenzo/Alico
B4: LISTA DE PRECIOS EN PESOS
B5: DD | C5: 1000 | D5: 1220 | E5: 1500 | G5: NEGRA | H5: 1000 | I5: 1245 | J5: 1500
B6: 16 | C6: =SUM(C16*0.07)+C16 -> 2328.3786 | D6: =SUM(C16*0.04)+C16 -> 2263.0969 | E6: =SUM(C16*0.04)+C16 -> 2263.0969 | G6: 1.6 | H6: XXX | I6: XXX | J6: XXX
B7: 18 | C7: =SUM(C16*0.07)+C16 -> 2328.3786 | D7: =SUM(C16*0.04)+C16 -> 2263.0969 | E7: =SUM(C16*0.04)+C16 -> 2263.0969 | G7: 2 | H7: =SUM(H16*0.14)+H16 -> 2122.0129 | I7: =SUM(H16*0.11)+H16 -> 2066.1704 | J7: XXX
B8: 12,14 y 20 | C8: =SUM(C16*0.08)+C16 -> 2350.1391 | D8: =SUM(C16*0.05)+C16 -> 2284.8575 | E8: =SUM(C16*0.05)+C16 -> 2284.8575 | G8: 2.5 | H8: =SUM(H16*0.12)+H16 -> 2084.7846 | I8: =SUM(H16*0.09)+H16 -> 2028.9421 | J8: XXX
B9: 22 | C9: =SUM(C16*0.1)+C16 -> 2393.6602 | D9: =SUM(C16*0.07)+C16 -> 2328.3786 | E9: =SUM(C16*0.07)+C16 -> 2328.3786 | G9: 3.17 | H9: =SUM(H16*0.11)+H16 -> 2066.1704 | I9: =SUM(H16*0.08)+H16 -> 2010.328 | J9: =SUM(H16*0.08)+H16 -> 2010.328
B10: 0.65 | C10: =SUM(C16*0.12)+C16 -> 2437.1813 | D10: =SUM(C16*0.09)+C16 -> 2371.8996 | E10: XXX | G10: 4,75 Y 4.00 | H10: =SUM(H16*0.1)+H16 -> 2047.5563 | I10: =SUM(H16*0.07+H16) -> 1991.7138 | J10: =SUM(H16*0.07)+H16 -> 1991.7138
B11: 24 | C11: =SUM(C16*0.16)+C16 -> 2524.2235 | D11: =SUM(C16*0.13)+C16 -> 2458.9418 | E11: XXX | G11: 6.35 | H11: =SUM(H16*0.11)+H16 -> 2066.1704 | I11: =SUM(H16*0.08)+H16 -> 2010.328 | J11: =SUM(H16*0.08)+H16 -> 2010.328
B12: 26 | C12: =SUM(C16*0.2)+C16 -> 2611.2657 | D12: =SUM(C16*0.15)+C16 -> 2502.4629 | E12: XXX | G12: 8 | H12: =SUM(H16*0.11)+H16 -> 2066.1704 | I12: =SUM(H16*0.08)+H16 -> 2010.328 | J12: =SUM(H16*0.08)+H16 -> 2010.328
B13: 27 | C13: =SUM(C16*0.26)+C16 -> 2741.8289 | D13: XXX | E13: XXX | G13: 9.52 | H13: =SUM(H16*0.12)+H16 -> 2084.7846 | I13: =SUM(H16*0.09)+H16 -> 2028.9421 | J13: =SUM(H16*0.1)+H16 -> 2047.5563
B14: 30 | C14: =SUM(C16*0.32)+C16 -> 2872.3922 | D14: XXX | E14: XXX | G14: 12.7 | H14: =SUM(H16*0.12)+H16 -> 2084.7846 | I14: =SUM(H16*0.09)+H16 -> 2028.9421 | J14: =SUM(H16*0.1)+H16 -> 2047.5563
B16: BASE | C16: =SUM(INICIO!K23) -> 2176.0547 | G16: BASE | H16: =SUM(INICIO!Q23) -> 1861.4148
